<?xml version="1.0" ?>
<!-- =================================================================================== -->
<!-- |    This document was autogenerated by xacro from /home/er4-user/ws/install/clr_mujoco_config/share/clr_mujoco_config/urdf/clr_xacro.urdf | -->
<!-- |    EDITING THIS FILE BY HAND IS NOT RECOMMENDED                                 | -->
<!-- =================================================================================== -->
<robot name="clr">
	<link name="world"/>
	<material name="red">
		<color rgba="1.0 0 0 1"/>
	</material>
	<material name="green">
		<color rgba="0 1.0 0 1"/>
	</material>
	<material name="blue">
		<color rgba="0 0 1.0 1"/>
	</material>
	<material name="gray">
		<color rgba="0.85 0.85 0.85 1.0"/>
	</material>
	<!-- CLR BASE JOINT -->
	<joint name="clr_base_joint" type="fixed">
		<parent link="world"/>
		<child link="clr_base"/>
		<origin rpy="0 0 0" xyz="0 0 0"/>
	</joint>
	<!-- CLR BASE -->
	<link name="clr_base">
		<visual>
			<geometry>
				<mesh filename="decomposed/clr_base/clr_base.obj"/>
			</geometry>
		</visual>
	</link>
	<joint name="vention_rail_base_joint" type="fixed">
		<parent link="clr_base"/>
		<child link="vention_rail_base_link"/>
		<origin xyz="0.0874537 0.114017 0.300000"/>
	</joint>
	<link name="vention_rail_base_link">
		<visual>
			<origin rpy="0 0 0" xyz="0 0 0.045"/>
			<geometry>
				<mesh filename="full/rail_des_live_body.obj"/>
			</geometry>
		</visual>
		<inertial>
			<mass value="38.47"/>
			<inertia ixx="0.46604111" ixy="0.0" ixz="0.0" iyy="0.46480515" iyz="-0.002668667" izz="0.1561"/>
		</inertial>
	</link>
	<link name="vention_rail_carriage">
		<visual>
			<geometry>
				<mesh filename="full/rail_des_live_carriage.obj"/>
			</geometry>
		</visual>
		<inertial>
			<mass value="2.937"/>
			<inertia ixx="0.0125" ixy="0.0" ixz="0.0" iyy="0.0287" iyz="0.0" izz="0.0199"/>
		</inertial>
	</link>
	<joint name="vention_rail_base_to_carriage" type="prismatic">
		<origin rpy="0 0 0" xyz="-0.96975 0 0.09600"/>
		<parent link="vention_rail_base_link"/>
		<child link="vention_rail_carriage"/>
		<limit effort="1000" lower="0" upper="2.0" velocity="0.15"/>
	</joint>
	<link name="vention_rail_gearbox">
		<visual>
			<geometry>
				<mesh filename="full/rail_des_gearbox.obj"/>
			</geometry>
		</visual>
	</link>
	<joint name="vention_rail_base_to_gearbox" type="fixed">
		<origin rpy="0 0 0" xyz="-1.3308 0 0.05455"/>
		<parent link="vention_rail_base_link"/>
		<child link="vention_rail_gearbox"/>
	</joint>
	<link name="vention_rail_motor">
		<visual>
			<geometry>
				<box size="0.086 0.086 0.226"/>
			</geometry>
			<material name="vention_rail_motor">
				<color rgba="0.8 0.8 0.8 1"/>
			</material>
		</visual>
	</link>
	<joint name="vention_rail_gearbox_to_motor" type="fixed">
		<origin rpy="0 0 0" xyz="-0.00555 0 0.19955"/>
		<parent link="vention_rail_gearbox"/>
		<child link="vention_rail_motor"/>
	</joint>
	<link name="vention_rail_cable_0">
		<visual>
			<geometry>
				<cylinder length="0.075" radius="0.015"/>
			</geometry>
			<material name="vention_rail_cable_0">
				<color rgba="0.8 0.8 0.8 1"/>
			</material>
		</visual>
	</link>
	<joint name="vention_motor_to_cable_0" type="fixed">
		<origin rpy="1.5707963267948966 0 0" xyz="0.0231 -0.0805 0.098"/>
		<parent link="vention_rail_motor"/>
		<child link="vention_rail_cable_0"/>
	</joint>
	<link name="vention_rail_cable_1">
		<visual>
			<geometry>
				<cylinder length="0.075" radius="0.015"/>
			</geometry>
			<material name="vention_rail_cable_1s">
				<color rgba="0.8 0.8 0.8 1"/>
			</material>
		</visual>
	</link>
	<joint name="vention_motor_to_cable_1" type="fixed">
		<origin rpy="1.5707963267948966 0 0" xyz="-0.0231 -0.0805 0.098"/>
		<parent link="vention_rail_motor"/>
		<child link="vention_rail_cable_1"/>
	</joint>
	<link name="vention_rail_cable_collision">
	</link>
	<joint name="vention_motor_to_cable_collision" type="fixed">
		<origin rpy="0 0 0" xyz="0 -0.1573 0.0749"/>
		<parent link="vention_rail_motor"/>
		<child link="vention_rail_cable_collision"/>
	</joint>
	<joint name="clr_carriage_base_joint" type="fixed">
		<parent link="vention_rail_carriage"/>
		<child link="clr_carriage"/>
		<origin xyz="-0.003624 -0.0900 0.0185"/>
	</joint>
	<link name="clr_carriage">
		<visual>
			<geometry>
				<mesh filename="full/clr_carriage.obj"/>
			</geometry>
		</visual>
	</link>
	<!-- SAFETY_LIGHTS -->
	<material name="safety_light_blue">
		<color rgba="0 0 0.5 0.8"/>
	</material>
	<link name="motor_side_estop_light">
		<visual>
			<geometry>
				<box size="0.05 0.05 0.381"/>
			</geometry>
			<material name="safety_light_blue"/>
		</visual>
	</link>
	<joint name="motor_side_estop_light_joint" type="fixed">
		<parent link="clr_base"/>
		<child link="motor_side_estop_light"/>
		<origin rpy="0 0 0" xyz="-0.925 -0.272 0.914"/>
	</joint>
	<link name="end_estop_light">
		<visual>
			<geometry>
				<box size="0.05 0.05 0.381"/>
			</geometry>
			<material name="safety_light_blue"/>
		</visual>
	</link>
	<joint name="end_estop_light_joint" type="fixed">
		<parent link="clr_base"/>
		<child link="end_estop_light"/>
		<origin rpy="0 0 0" xyz="0.929 -0.272 0.714"/>
	</joint>
	<joint name="lower_lift_plate_base_joint" type="fixed">
		<parent link="clr_carriage"/>
		<child link="lower_lift_plate"/>
		<origin rpy="0 0 0" xyz="0 0 0.054525"/>
	</joint>
	<link name="lower_lift_plate">
		<visual>
			<geometry>
				<box size="0.310 0.310 0.01905"/>
			</geometry>
			<material name="lower_lift_plate">
				<color rgba="0.8 0.8 0.8 1"/>
			</material>
		</visual>
	</link>
	<joint name="ewellix_lift_base_joint" type="fixed">
		<parent link="lower_lift_plate"/>
		<child link="ewellix_lift_lower_link"/>
		<origin rpy="0 0 0" xyz="0 0 0.295"/>
	</joint>
	<!--LOWER-->
	<link name="ewellix_lift_lower_link">
		<inertial>
			<mass value="19.52107"/>
			<inertia ixx="0.46604111" ixy="0.0" ixz="0.0" iyy="0.46480515" iyz="-0.002668667" izz="0.1561"/>
		</inertial>
		<visual>
			<geometry>
				<mesh filename="full/lift_low_700mm.obj"/>
			</geometry>
			<material name="gray"/>
		</visual>
	</link>
	<!--MIDDLE-->
	<link name="ewellix_lift_middle_link">
		<inertial>
			<mass value="15.593303"/>
			<inertia ixx="0.34930648" ixy="0.0" ixz="0.0" iyy="0.34930648" iyz="0.0" izz="0.095393471"/>
		</inertial>
		<visual>
			<geometry>
				<mesh filename="full/lift_mid_700mm.obj"/>
			</geometry>
			<material name="gray"/>
		</visual>
	</link>
	<!--HIGHER-->
	<link name="ewellix_lift_higher_link">
		<inertial>
			<mass value="15.166778"/>
			<inertia ixx="0.35552099" ixy="9.631e-06" ixz="2.2848e-05" iyy="0.35552876" iyz="5.491e-05" izz="0.069925583"/>
		</inertial>
		<visual>
			<geometry>
				<mesh filename="full/lift_high_700mm.obj"/>
			</geometry>
			<material name="gray"/>
		</visual>
	</link>
	<!--LOWER TO HIGHER (PRISMATIC)-->
	<joint name="ewellix_lift_lower_to_higher" type="prismatic">
		<parent link="ewellix_lift_lower_link"/>
		<child link="ewellix_lift_higher_link"/>
		<origin rpy="0 0 0" xyz="0 0 0.0915"/>
		<axis xyz="0 0 1"/>
		<limit effort="1000" lower="0" upper="0.7" velocity="1"/>
	</joint>
	<!--MIDDLE MIMIC HIGHER (PRISMATIC MIMIC)-->
	<joint name="middle_mimic_higher" type="prismatic">
		<parent link="ewellix_lift_higher_link"/>
		<child link="ewellix_lift_middle_link"/>
		<origin rpy="0 0 0" xyz="0 0 -0.03397"/>
		<axis xyz="0 0 -1"/>
		<limit effort="1000" lower="0" upper="0.35" velocity="1"/>
		<mimic joint="ewellix_lift_lower_to_higher" multiplier="0.5" offset="0"/>
	</joint>
	<link name="ewellix_lift_tip_link"/>
	<joint name="ewellix_lift_tip_joint" type="fixed">
		<parent link="ewellix_lift_higher_link"/>
		<child link="ewellix_lift_tip_link"/>
		<origin rpy="0 0 0" xyz="0 0 0.244"/>
	</joint>
	<joint name="lift_camera_mount_base_joint" type="fixed">
		<parent link="ewellix_lift_lower_link"/>
		<child link="lift_camera_mount"/>
		<origin rpy="0 0 0" xyz="-0.0772 0.095 0.2635"/>
	</joint>
	<link name="lift_camera_mount">
		<visual>
			<geometry>
				<mesh filename="full/lift_camera_mount.obj"/>
			</geometry>
			<material name="lift_camera_mount">
				<color rgba="0.8 0.8 0.8 1"/>
			</material>
		</visual>
	</link>
	<!-- ^^ Avoid Error   material 'aluminum' is not unique.
        This doesn't work in old versions (v4.51) of the realsense2_description because there are no header guards at all
        Version 4.54.1 has header guards but they don't work as expected.
    -->
	<!-- Pose obtained from Measuring by hand. Origin is lift_camera_bottom_screw_frame-->
	<!-- <xacro:include filename="$(find realsense2_description)/urdf/_d435.urdf.xacro" />
    <xacro:sensor_d435 parent="${tf_prefix}lift_camera_mount" use_nominal_extrinsics="true" use_mesh="true" name="hand_measured_lift_camera">
        <origin xyz="0.076 0.01 -0.1725" rpy="3.1415 0 1.5708"/>
    </xacro:sensor_d435> -->
	<!-- camera body, with origin at bottom screw mount -->
	<joint name="lift_camera_joint" type="fixed">
		<origin rpy="-3.0512 -0.0276 1.5884" xyz="-0.007666 0.1069 0.3866"/>
		<parent link="lower_lift_plate"/>
		<child link="lift_camera_bottom_screw_frame"/>
	</joint>
	<link name="lift_camera_bottom_screw_frame"/>
	<joint name="lift_camera_link_joint" type="fixed">
		<origin rpy="0 0 0" xyz="0.010600000000000002 0.0175 0.0125"/>
		<parent link="lift_camera_bottom_screw_frame"/>
		<child link="lift_camera_link"/>
	</joint>
	<link name="lift_camera_link">
		<visual>
			<!-- the mesh origin is at front plate in between the two infrared camera axes -->
			<origin rpy="1.5707963267948966 0 1.5707963267948966" xyz="0.0043 -0.0175 0"/>
			<geometry>
				<mesh filename="full/d435.obj"/>
			</geometry>
		</visual>
		<inertial>
			<!-- The following are not reliable values, and should not be used for modeling -->
			<mass value="0.072"/>
			<origin xyz="0 0 0"/>
			<inertia ixx="0.003881243" ixy="0.0" ixz="0.0" iyy="0.000498940" iyz="0.0" izz="0.003879257"/>
		</inertial>
	</link>
	<!-- camera depth joints and links -->
	<joint name="lift_camera_depth_joint" type="fixed">
		<origin rpy="0 0 0" xyz="0 0 0"/>
		<parent link="lift_camera_link"/>
		<child link="lift_camera_depth_frame"/>
	</joint>
	<link name="lift_camera_depth_frame"/>
	<joint name="lift_camera_depth_optical_joint" type="fixed">
		<origin rpy="-1.5707963267948966 0 -1.5707963267948966" xyz="0 0 0"/>
		<parent link="lift_camera_depth_frame"/>
		<child link="lift_camera_depth_optical_frame"/>
	</joint>
	<link name="lift_camera_depth_optical_frame"/>
	<!-- camera left IR joints and links -->
	<joint name="lift_camera_infra1_joint" type="fixed">
		<origin rpy="0 0 0" xyz="0 0.0 0"/>
		<parent link="lift_camera_link"/>
		<child link="lift_camera_infra1_frame"/>
	</joint>
	<link name="lift_camera_infra1_frame"/>
	<joint name="lift_camera_infra1_optical_joint" type="fixed">
		<origin rpy="-1.5707963267948966 0 -1.5707963267948966" xyz="0 0 0"/>
		<parent link="lift_camera_infra1_frame"/>
		<child link="lift_camera_infra1_optical_frame"/>
	</joint>
	<link name="lift_camera_infra1_optical_frame"/>
	<!-- camera right IR joints and links -->
	<joint name="lift_camera_infra2_joint" type="fixed">
		<origin rpy="0 0 0" xyz="0 -0.05 0"/>
		<parent link="lift_camera_link"/>
		<child link="lift_camera_infra2_frame"/>
	</joint>
	<link name="lift_camera_infra2_frame"/>
	<joint name="lift_camera_infra2_optical_joint" type="fixed">
		<origin rpy="-1.5707963267948966 0 -1.5707963267948966" xyz="0 0 0"/>
		<parent link="lift_camera_infra2_frame"/>
		<child link="lift_camera_infra2_optical_frame"/>
	</joint>
	<link name="lift_camera_infra2_optical_frame"/>
	<!-- camera color joints and links -->
	<joint name="lift_camera_color_joint" type="fixed">
		<origin rpy="0 0 0" xyz="0 0.015 0"/>
		<parent link="lift_camera_link"/>
		<child link="lift_camera_color_frame"/>
	</joint>
	<link name="lift_camera_color_frame"/>
	<joint name="lift_camera_color_optical_joint" type="fixed">
		<origin rpy="-1.5707963267948966 0 -1.5707963267948966" xyz="0 0 0"/>
		<parent link="lift_camera_color_frame"/>
		<child link="lift_camera_color_optical_frame"/>
	</joint>
	<link name="lift_camera_color_optical_frame"/>
	<joint name="upper_lift_plate_base_joint" type="fixed">
		<parent link="ewellix_lift_higher_link"/>
		<child link="upper_lift_plate"/>
		<origin rpy="0 0 0" xyz="0 0 0.253525"/>
	</joint>
	<link name="upper_lift_plate">
		<visual>
			<geometry>
				<box size="0.225 0.225 0.01905"/>
			</geometry>
			<material name="upper_lift_plate">
				<color rgba="0.8 0.8 0.8 1"/>
			</material>
		</visual>
	</link>
	<link name="right_angle_mount">
		<visual>
			<geometry>
				<mesh filename="full/right_angle_mount.obj"/>
			</geometry>
		</visual>
	</link>
	<!-- UPPER_LIFT_PLATE_TO_RIGHT_ANGLE_MOUNT -->
	<joint name="upper_lift_plate_to_right_angle_mount" type="fixed">
		<parent link="upper_lift_plate"/>
		<child link="right_angle_mount"/>
		<origin rpy="0 0 0" xyz="0 0 0.009525"/>
	</joint>
	<joint name="ur10e_mount_plate_base_joint" type="fixed">
		<parent link="right_angle_mount"/>
		<child link="ur10e_mount_plate"/>
		<origin rpy="0 0 0" xyz="0 0.112509 0.112509"/>
	</joint>
	<link name="ur10e_mount_plate">
		<visual>
			<geometry>
				<mesh filename="full/ur10e_plate.obj"/>
			</geometry>
		</visual>
	</link>
	<link name="ur10e_mount_link"/>
	<joint name="chonkur_mount_joint" type="fixed">
		<parent link="ur10e_mount_plate"/>
		<child link="ur10e_mount_link"/>
		<origin rpy="-1.5707963267948966 3.141592653589793 0" xyz="0 0.0225 0"/>
	</joint>
	<!--
    Base UR robot series xacro macro.
    NOTE this is NOT a URDF. It cannot directly be loaded by consumers
    expecting a flattened '.urdf' file. See the top-level '.xacro' for that
    (but note that .xacro must still be processed by the xacro command).
    This file models the base kinematic chain of a UR robot, which then gets
    parameterised by various configuration files to convert it into a UR3(e),
    UR5(e), UR10(e) or UR16e.
    NOTE the default kinematic parameters (i.e., link lengths, frame locations,
    offsets, etc) do not correspond to any particular robot. They are defaults
    only. There WILL be non-zero offsets between the Forward Kinematics results
    in TF (i.e., robot_state_publisher) and the values reported by the Teach
    Pendant.
    For accurate (and robot-specific) transforms, the 'kinematics_parameters_file'
    parameter MUST point to a .yaml file containing the appropriate values for
    the targeted robot.
    If using the UniversalRobots/Universal_Robots_ROS_Driver, follow the steps
    described in the readme of that repository to extract the kinematic
    calibration from the controller and generate the required .yaml file.
    Main author of the migration to yaml configs Ludovic Delval.
    Contributors to previous versions (in no particular order)
     - Denis Stogl
     - Lovro Ivanov
     - Felix Messmer
     - Kelsey Hawkins
     - Wim Meeussen
     - Shaun Edwards
     - Nadia Hammoudeh Garcia
     - Dave Hershberger
     - G. vd. Hoorn
     - Philip Long
     - Dave Coleman
     - Miguel Prada
     - Mathias Luedtke
     - Marcel Schnirring
     - Felix von Drigalski
     - Felix Exner
     - Jimmy Da Silva
     - Ajit Krisshna N L
     - Muhammad Asif Rana
  -->
	<!--
    NOTE the macro defined in this file is NOT part of the public API of this
          package. Users CANNOT rely on this file being available, or stored in
          this location. Nor can they rely on the existence of the macro.
  -->
	<!-- trying to reuse ur control launch files. So cannot pass in any additional args to the xacro.-->
	<!-- Add URDF transmission elements (for ros_control) -->
	<!--<xacro:ur_arm_transmission prefix="${prefix}" hw_interface="${transmission_hw_interface}" />-->
	<!-- Placeholder for ros2_control transmission which don't yet exist -->
	<!-- links -  main serial chain -->
	<link name="base_link"/>
	<link name="base_link_inertia">
		<visual>
			<origin rpy="0 0 3.141592653589793" xyz="0 0 0"/>
			<geometry>
				<mesh filename="full/base.obj"/>
			</geometry>
		</visual>
		<inertial>
			<mass value="4.0"/>
			<origin rpy="0 0 0" xyz="0 0 0"/>
			<inertia ixx="0.0061063308908" ixy="0.0" ixz="0.0" iyy="0.0061063308908" iyz="0.0" izz="0.01125"/>
		</inertial>
	</link>
	<link name="shoulder_link">
		<visual>
			<origin rpy="0 0 3.141592653589793" xyz="0 0 0"/>
			<geometry>
				<mesh filename="full/shoulder.obj"/>
			</geometry>
		</visual>
		<inertial>
			<mass value="7.369"/>
			<origin rpy="1.570796326794897 0 0" xyz="0.021 -0.027 0.0"/>
			<inertia ixx="0.03408" ixy="2e-05" ixz="-0.00425" iyy="0.03529" iyz="8e-05" izz="0.02156"/>
		</inertial>
	</link>
	<link name="upper_arm_link">
		<visual>
			<origin rpy="1.5707963267948966 0 -1.5707963267948966" xyz="0 0 0.1762"/>
			<geometry>
				<mesh filename="full/upperarm.obj"/>
			</geometry>
		</visual>
		<inertial>
			<mass value="13.051"/>
			<origin rpy="0 0 0" xyz="-0.2327 0.0 0.158"/>
			<inertia ixx="0.02814" ixy="5e-05" ixz="-0.01561" iyy="0.77068" iyz="2e-05" izz="0.76943"/>
		</inertial>
	</link>
	<link name="forearm_link">
		<visual>
			<origin rpy="1.5707963267948966 0 -1.5707963267948966" xyz="0 0 0.0393"/>
			<geometry>
				<mesh filename="full/forearm.obj"/>
			</geometry>
		</visual>
		<inertial>
			<mass value="3.989"/>
			<origin rpy="0 0 0" xyz="-0.33155 0.0 0.068"/>
			<inertia ixx="0.01014" ixy="8e-05" ixz="0.00916" iyy="0.30928" iyz="0.0" izz="0.30646"/>
		</inertial>
	</link>
	<link name="wrist_1_link">
		<visual>
			<origin rpy="1.5707963267948966 0 0" xyz="0 0 -0.135"/>
			<geometry>
				<mesh filename="full/wrist1.obj"/>
			</geometry>
		</visual>
		<inertial>
			<mass value="2.1"/>
			<origin rpy="1.570796326794897 0 0" xyz="0.0 -0.018 0.007"/>
			<inertia ixx="0.00296" ixy="-1e-05" ixz="0.0" iyy="0.00222" iyz="-0.00024" izz="0.00258"/>
		</inertial>
	</link>
	<link name="wrist_2_link">
		<visual>
			<origin rpy="0 0 0" xyz="0 0 -0.12"/>
			<geometry>
				<mesh filename="full/wrist2.obj"/>
			</geometry>
		</visual>
		<inertial>
			<mass value="1.98"/>
			<origin rpy="-1.570796326794897 0 0" xyz="0.0 0.018 -0.007"/>
			<inertia ixx="0.00296" ixy="-1e-05" ixz="0.0" iyy="0.00222" iyz="-0.00024" izz="0.00258"/>
		</inertial>
	</link>
	<link name="wrist_3_link">
		<visual>
			<origin rpy="1.5707963267948966 0 0" xyz="0 0 -0.1168"/>
			<geometry>
				<mesh filename="full/wrist3.obj"/>
			</geometry>
		</visual>
		<inertial>
			<mass value="0.615"/>
			<origin rpy="0 0 0" xyz="0.0 0.0 -0.026"/>
			<inertia ixx="0.0004" ixy="0.0" ixz="0.0" iyy="0.00041" iyz="0.0" izz="0.00034"/>
		</inertial>
	</link>
	<!-- base_joint fixes base_link to the environment -->
	<joint name="base_joint" type="fixed">
		<origin rpy="0 0 0" xyz="0 0 0"/>
		<parent link="ur10e_mount_link"/>
		<child link="base_link"/>
	</joint>
	<!-- joints - main serial chain -->
	<joint name="base_link-base_link_inertia" type="fixed">
		<parent link="base_link"/>
		<child link="base_link_inertia"/>
		<!-- 'base_link' is REP-103 aligned (so X+ forward), while the internal
           frames of the robot/controller have X+ pointing backwards.
           Use the joint between 'base_link' and 'base_link_inertia' (a dummy
           link/frame) to introduce the necessary rotation over Z (of pi rad).
      -->
		<origin rpy="0 0 3.141592653589793" xyz="0 0 0"/>
	</joint>
	<joint name="shoulder_pan_joint" type="revolute">
		<parent link="base_link_inertia"/>
		<child link="shoulder_link"/>
		<origin rpy="0 0 -2.7317235812632235e-07" xyz="0 0 0.1806550577141417"/>
		<axis xyz="0 0 1"/>
		<limit effort="330.0" lower="-6.283185307179586" upper="6.283185307179586" velocity="2.0943951023931953"/>
		<dynamics damping="0" friction="0"/>
	</joint>
	<joint name="shoulder_lift_joint" type="revolute">
		<parent link="shoulder_link"/>
		<child link="upper_arm_link"/>
		<origin rpy="1.570381475627817 0 -2.2029967076786605e-06" xyz="-2.635189613817671e-05 0 0"/>
		<axis xyz="0 0 1"/>
		<limit effort="330.0" lower="-6.283185307179586" upper="6.283185307179586" velocity="2.0943951023931953"/>
		<dynamics damping="0" friction="0"/>
	</joint>
	<joint name="elbow_joint" type="revolute">
		<parent link="upper_arm_link"/>
		<child link="forearm_link"/>
		<origin rpy="0.00010428075699773081 0.00018552869605352983 -3.2916500637162023e-06" xyz="-0.612202788193267 0 0"/>
		<axis xyz="0 0 1"/>
		<limit effort="150.0" lower="-3.141592653589793" upper="3.141592653589793" velocity="3.141592653589793"/>
		<dynamics damping="0" friction="0"/>
	</joint>
	<joint name="wrist_1_joint" type="revolute">
		<parent link="forearm_link"/>
		<child link="wrist_1_link"/>
		<origin rpy="3.13249510516966 -3.141108069938163 3.1415911453948597" xyz="-0.5712349762730509 0.0015803278398461914 0.17370440560593067"/>
		<axis xyz="0 0 1"/>
		<limit effort="56.0" lower="-6.283185307179586" upper="6.283185307179586" velocity="3.141592653589793"/>
		<dynamics damping="0" friction="0"/>
	</joint>
	<joint name="wrist_2_joint" type="revolute">
		<parent link="wrist_1_link"/>
		<child link="wrist_2_link"/>
		<origin rpy="1.5697679836038372 0 -5.283130196168106e-08" xyz="8.877227386249507e-06 -0.11976304262789399 0.00012315755283957448"/>
		<axis xyz="0 0 1"/>
		<limit effort="56.0" lower="-6.283185307179586" upper="6.283185307179586" velocity="3.141592653589793"/>
		<dynamics damping="0" friction="0"/>
	</joint>
	<joint name="wrist_3_joint" type="revolute">
		<parent link="wrist_2_link"/>
		<child link="wrist_3_link"/>
		<origin rpy="1.5712545685169859 3.141592653589793 3.1415924319450474" xyz="-1.7010162555617382e-05 0.11530121453237739 5.283583080456427e-05"/>
		<axis xyz="0 0 1"/>
		<limit effort="56.0" lower="-6.283185307179586" upper="6.283185307179586" velocity="3.141592653589793"/>
		<dynamics damping="0" friction="0"/>
	</joint>
	<link name="ft_frame"/>
	<joint name="wrist_3_link-ft_frame" type="fixed">
		<parent link="wrist_3_link"/>
		<child link="ft_frame"/>
		<origin rpy="3.141592653589793 0 0" xyz="0 0 0"/>
	</joint>
	<!-- ROS-Industrial 'base' frame - base_link to UR 'Base' Coordinates transform -->
	<link name="base"/>
	<joint name="base_link-base_fixed_joint" type="fixed">
		<!-- Note the rotation over Z of pi radians - as base_link is REP-103
           aligned (i.e., has X+ forward, Y+ left and Z+ up), this is needed
           to correctly align 'base' with the 'Base' coordinate system of
           the UR controller.
      -->
		<origin rpy="0 0 3.141592653589793" xyz="0 0 0"/>
		<parent link="base_link"/>
		<child link="base"/>
	</joint>
	<!-- ROS-Industrial 'flange' frame - attachment point for EEF models -->
	<link name="flange"/>
	<joint name="wrist_3-flange" type="fixed">
		<parent link="wrist_3_link"/>
		<child link="flange"/>
		<origin rpy="0 -1.5707963267948966 -1.5707963267948966" xyz="0 0 0"/>
	</joint>
	<!-- ROS-Industrial 'tool0' frame - all-zeros tool frame -->
	<link name="tool0"/>
	<joint name="flange-tool0" type="fixed">
		<!-- default toolframe - X+ left, Y+ up, Z+ front -->
		<origin rpy="1.5707963267948966 0 1.5707963267948966" xyz="0 0 0"/>
		<parent link="flange"/>
		<child link="tool0"/>
	</joint>
	<!-- END EFFECTOR STACK -->
	<joint name="endeff_stack_base_joint" type="fixed">
		<parent link="tool0"/>
		<child link="mtc_robot_side"/>
		<origin rpy="0 0 1.5707963267948966" xyz="0 0 0"/>
	</joint>
	<link name="mtc_robot_side">
		<visual>
			<geometry>
				<mesh filename="full/mtc_robot_side.obj"/>
			</geometry>
		</visual>
	</link>
	<joint name="mtc_robot_to_effector_side_joint" type="fixed">
		<parent link="mtc_robot_side"/>
		<child link="mtc_effector_side"/>
		<origin rpy="0 0 0" xyz="0 0 0.008763"/>
	</joint>
	<link name="mtc_effector_side">
		<visual>
			<geometry>
				<mesh filename="full/mtc_effector_side.obj"/>
			</geometry>
		</visual>
	</link>
	<joint name="mtc_effector_side_to_realsense_mount" type="fixed">
		<parent link="mtc_effector_side"/>
		<child link="ur_realsense_mount"/>
		<origin rpy="0 0 0" xyz="0 0 0.023684"/>
	</joint>
	<link name="ur_realsense_mount">
		<visual>
			<geometry>
				<mesh filename="full/ur_realsense_short_mount_tube.obj"/>
			</geometry>
			<material name="ur_realsense_mount">
				<color rgba="0.1 0.1 0.1 1.0"/>
			</material>
		</visual>
	</link>
	<!-- camera body, with origin at bottom screw mount -->
	<joint name="wrist_mounted_camera_joint" type="fixed">
		<origin rpy="0.136 -1.429 -0.128" xyz="-0.064 -0.003 0.016"/>
		<parent link="ur_realsense_mount"/>
		<child link="wrist_mounted_camera_bottom_screw_frame"/>
	</joint>
	<link name="wrist_mounted_camera_bottom_screw_frame"/>
	<joint name="wrist_mounted_camera_link_joint" type="fixed">
		<origin rpy="0 0 0" xyz="0.010600000000000002 0.0175 0.0125"/>
		<parent link="wrist_mounted_camera_bottom_screw_frame"/>
		<child link="wrist_mounted_camera_link"/>
	</joint>
	<link name="wrist_mounted_camera_link">
		<visual>
			<!-- the mesh origin is at front plate in between the two infrared camera axes -->
			<origin rpy="1.5707963267948966 0 1.5707963267948966" xyz="0.0043 -0.0175 0"/>
			<geometry>
				<mesh filename="full/d435.obj"/>
			</geometry>
		</visual>
		<inertial>
			<!-- The following are not reliable values, and should not be used for modeling -->
			<mass value="0.072"/>
			<origin xyz="0 0 0"/>
			<inertia ixx="0.003881243" ixy="0.0" ixz="0.0" iyy="0.000498940" iyz="0.0" izz="0.003879257"/>
		</inertial>
	</link>
	<!-- camera depth joints and links -->
	<joint name="wrist_mounted_camera_depth_joint" type="fixed">
		<origin rpy="0 0 0" xyz="0 0 0"/>
		<parent link="wrist_mounted_camera_link"/>
		<child link="wrist_mounted_camera_depth_frame"/>
	</joint>
	<link name="wrist_mounted_camera_depth_frame"/>
	<joint name="wrist_mounted_camera_depth_optical_joint" type="fixed">
		<origin rpy="-1.5707963267948966 0 -1.5707963267948966" xyz="0 0 0"/>
		<parent link="wrist_mounted_camera_depth_frame"/>
		<child link="wrist_mounted_camera_depth_optical_frame"/>
	</joint>
	<link name="wrist_mounted_camera_depth_optical_frame"/>
	<!-- camera left IR joints and links -->
	<joint name="wrist_mounted_camera_infra1_joint" type="fixed">
		<origin rpy="0 0 0" xyz="0 0.0 0"/>
		<parent link="wrist_mounted_camera_link"/>
		<child link="wrist_mounted_camera_infra1_frame"/>
	</joint>
	<link name="wrist_mounted_camera_infra1_frame"/>
	<joint name="wrist_mounted_camera_infra1_optical_joint" type="fixed">
		<origin rpy="-1.5707963267948966 0 -1.5707963267948966" xyz="0 0 0"/>
		<parent link="wrist_mounted_camera_infra1_frame"/>
		<child link="wrist_mounted_camera_infra1_optical_frame"/>
	</joint>
	<link name="wrist_mounted_camera_infra1_optical_frame"/>
	<!-- camera right IR joints and links -->
	<joint name="wrist_mounted_camera_infra2_joint" type="fixed">
		<origin rpy="0 0 0" xyz="0 -0.05 0"/>
		<parent link="wrist_mounted_camera_link"/>
		<child link="wrist_mounted_camera_infra2_frame"/>
	</joint>
	<link name="wrist_mounted_camera_infra2_frame"/>
	<joint name="wrist_mounted_camera_infra2_optical_joint" type="fixed">
		<origin rpy="-1.5707963267948966 0 -1.5707963267948966" xyz="0 0 0"/>
		<parent link="wrist_mounted_camera_infra2_frame"/>
		<child link="wrist_mounted_camera_infra2_optical_frame"/>
	</joint>
	<link name="wrist_mounted_camera_infra2_optical_frame"/>
	<!-- camera color joints and links -->
	<joint name="wrist_mounted_camera_color_joint" type="fixed">
		<origin rpy="0 0 0" xyz="0 0.015 0"/>
		<parent link="wrist_mounted_camera_link"/>
		<child link="wrist_mounted_camera_color_frame"/>
	</joint>
	<link name="wrist_mounted_camera_color_frame"/>
	<joint name="wrist_mounted_camera_color_optical_joint" type="fixed">
		<origin rpy="-1.5707963267948966 0 -1.5707963267948966" xyz="0 0 0"/>
		<parent link="wrist_mounted_camera_color_frame"/>
		<child link="wrist_mounted_camera_color_optical_frame"/>
	</joint>
	<link name="wrist_mounted_camera_color_optical_frame"/>
	<material name="dark_gray">
		<color rgba="0.2 0.2 0.2 1"/>
	</material>
	<material name="black">
		<color rgba="0 0 0 1"/>
	</material>
	<joint name="gripper_adapter_joint" type="fixed">
		<parent link="ur_realsense_mount"/>
		<child link="robotiq_hande_cb_adapter"/>
		<origin rpy="0 0 -1.5707963267948966" xyz="0 0 0.008"/>
	</joint>
	<link name="robotiq_hande_cb_adapter">
		<!--Not sure if these are right, based on the robotiq numbers for ur_to_robotiq_link-->
		<inertial>
			<mass value="0.01"/>
			<origin xyz="0 0 0"/>
			<inertia ixx="0.000044" ixy="0.0" ixz="0.0" iyy="0.000027" iyz="0.0" izz="0.000027"/>
		</inertial>
		<origin rpy="0 0 0" xyz="0 0 0"/>
		<visual>
			<geometry>
				<mesh filename="full/robotiq_hande_cb_adapter.obj" scale="1 1 1"/>
			</geometry>
			<material name="black"/>
		</visual>
	</link>
	<joint name="gripper_base_joint" type="fixed">
		<parent link="robotiq_hande_cb_adapter"/>
		<child link="gripper_base_link"/>
		<origin rpy="0 0 0" xyz="0.0 0.0 0.011"/>
	</joint>
	<link name="gripper_base_link">
		<inertial>
			<origin rpy="0 0 0" xyz="0 0 0.04607"/>
			<mass value="0.86387"/>
			<inertia ixx="1017560E-9" ixy="0" ixz="2235E-9" iyy="1028041E-9" iyz="0" izz="489810E-9"/>
		</inertial>
		<visual>
			<origin rpy="0 0 0" xyz="0 0 0"/>
			<geometry>
				<mesh filename="full/hande.obj" scale="0.001 0.001 0.001"/>
			</geometry>
			<material name="black"/>
		</visual>
	</link>
	<joint name="gripper_palm_joint" type="fixed">
		<parent link="gripper_base_link"/>
		<child link="gripper_palm_link"/>
		<origin rpy="0 0 0" xyz="0.0 0.0 0.0988"/>
	</joint>
	<link name="gripper_palm_link">
		<visual>
			<geometry>
				<sphere radius="0.007"/>
			</geometry>
			<material name="_green">
				<color rgba="0 1.0 0 0.5"/>
			</material>
		</visual>
	</link>
	<material name="hande_fingers_v6_dark_gray">
		<color rgba="0.2 0.2 0.2 1"/>
	</material>
	<link name="finger_1_link">
		<inertial>
			<origin rpy="0 0 0" xyz="0.0 0.0 0.0"/>
			<mass value="0.050019846"/>
			<inertia ixx="0.000060226393" ixy="-0.0000009852757" ixz="-0.00000994007986" iyy="0.000062464751" iyz="-0.0000028146120" izz="0.0000079760530"/>
		</inertial>
		<visual>
			<origin rpy="0 0 0" xyz="0.0 0.0 0.0"/>
			<geometry>
				<mesh filename="decomposed/finger_v6/finger_v6.obj" scale="1 1 1"/>
			</geometry>
			<material name="hande_fingers_v6_dark_gray"/>
		</visual>
	</link>
	<link name="finger_2_link">
		<inertial>
			<origin rpy="0 0 0" xyz="0.0 0.0 0.0"/>
			<mass value="0.050019846"/>
			<inertia ixx="0.000060226393" ixy="-0.0000009852757" ixz="-0.00000994007986" iyy="0.000062464751" iyz="-0.0000028146120" izz="0.0000079760530"/>
		</inertial>
		<visual>
			<origin rpy="0 0 0" xyz="0.0 0.0 0.0"/>
			<geometry>
				<mesh filename="decomposed/finger_v6/finger_v6.obj" scale="1 1 1"/>
			</geometry>
			<material name="hande_fingers_v6_dark_gray"/>
		</visual>
	</link>
	<joint name="finger_1_joint" type="prismatic">
		<origin rpy="0.0 0.0 0.0" xyz="0.00201401 -0.0032500000000000003 0.1005"/>
		<parent link="gripper_base_link"/>
		<child link="finger_1_link"/>
		<axis xyz="1 0 0"/>
		<limit effort="130" lower="0" upper="0.025" velocity="0.15"/>
	</joint>
	<joint name="finger_2_joint" type="prismatic">
		<origin rpy="0.0 0.0 3.141592653589793" xyz="-0.00201401 0.0032500000000000003 0.1005"/>
		<parent link="gripper_base_link"/>
		<child link="finger_2_link"/>
		<axis xyz="1 0 0"/>
		<limit effort="130" lower="0" upper="0.025" velocity="0.15"/>
		<mimic joint="finger_1_joint" multiplier="1" offset="0"/>
	</joint>
	<joint name="express_rack_joint" type="fixed">
		<parent link="world"/>
		<child link="express_rack"/>
		<origin rpy="1.5707963 0 0" xyz="0.508 1.1678 0.98425"/>
	</joint>
	<link name="express_rack">
		<!--TODO set proper inertia-->
		<inertial>
			<origin rpy="0 0 0" xyz="0.0 0.0 0.0"/>
			<mass value="0.0"/>
			<inertia ixx="0.1" ixy="0.0" ixz="0.0" iyy="0.1" iyz="0.0" izz="0.1"/>
		</inertial>
		<visual>
			<origin rpy="0 0 0" xyz="0.0 0.0 0.0"/>
			<geometry>
				<mesh filename="full/express_rack_mesh.obj" scale="0.0254 0.0254 0.0254"/>
			</geometry>
			<material name="gray"/>
		</visual>
	</link>
	<joint name="merlin_freezer_joint" type="fixed">
		<parent link="express_rack"/>
		<child link="wood_frame"/>
		<origin rpy="1.5707963 0 3.1415927" xyz="-0.2286 0.083 0"/>
	</joint>
	<link name="wood_frame">
		<visual>
			<geometry>
				<mesh filename="full/aso_locker_cavity_only.obj" scale="0.02527 0.02527 0.02527"/>
			</geometry>
			<material name="Gray">
				<color rgba="0.5 0.5 0.5 1.0"/>
			</material>
		</visual>
	</link>
	<link name="csm_faceplate_cover">
		<visual>
			<geometry>
				<mesh filename="full/csm_faceplate_cover.obj"/>
			</geometry>
			<material name="Gray">
				<color rgba="0.5 0.5 0.5 1.0"/>
			</material>
		</visual>
	</link>
	<joint name="faceplate_cover_joint" type="fixed">
		<parent link="wood_frame"/>
		<child link="csm_faceplate_cover"/>
		<origin rpy="1.5707963267948966 0 3.141592653589793" xyz="0.0 0.013 0.0"/>
	</joint>
	<link name="door_face">
  </link>
	<joint name="door_face" type="fixed">
		<parent link="csm_faceplate_cover"/>
		<child link="door_face"/>
		<origin rpy="0 0 0" xyz="0.0 0.0 0.0381"/>
	</joint>
	<!-- Seal section-->
	<!-- Replace visual and collision components of this link with stl eventually-->
	<link name="seal">
		<inertial>
			<origin rpy="0 0 0" xyz="0.0 0.0 0.0"/>
			<mass value="0.1"/>
			<inertia ixx="0.01" ixy="0.0" ixz="0.0" iyy="0.01" iyz="0.0" izz="0.01"/>
		</inertial>
		<!-- Right-->
		<visual>
			<geometry>
				<box size="0.0091 0.201 0.005"/>
			</geometry>
			<material name="Cyan">
				<color rgba="0.0 0.0 0.0 1.0"/>
			</material>
			<origin rpy="0 0 0" xyz="0.1554 0 0.0025"/>
		</visual>
		<!-- Left -->
		<visual>
			<geometry>
				<box size="0.0091 0.201 0.005"/>
			</geometry>
			<material name="Cyan">
				<color rgba="0.0 0.0 0.0 1.0"/>
			</material>
			<origin rpy="0 0 0" xyz="-0.1554 0 0.0025"/>
		</visual>
		<!-- Top-->
		<visual>
			<geometry>
				<box size="0.302 0.0091 0.005"/>
			</geometry>
			<material name="Cyan">
				<color rgba="0.0 0.0 0.0 1.0"/>
			</material>
			<origin rpy="0 0 0" xyz="0 0.1045 0.0025"/>
		</visual>
		<!-- Bottom -->
		<visual>
			<geometry>
				<box size="0.302 0.0091 0.005"/>
			</geometry>
			<material name="Cyan">
				<color rgba="0.0 0.0 0.0 1.0"/>
			</material>
			<origin rpy="0 0 0" xyz="0 -0.1045 0.0025"/>
		</visual>
	</link>
	<joint name="seal_to_face_joint" type="fixed">
		<parent link="csm_faceplate_cover"/>
		<child link="seal"/>
		<!-- Seal does not appear to be perfectly centered - introduce offsets -->
		<origin rpy="0 0 0" xyz="-0.001 -0.0015 0"/>
	</joint>
	<!-- Seal corners to help with cartesian waypoints - keep and modify these once above geometry is replaced with an stl -->
	<link name="seal_corner_1"/>
	<joint name="c1_to_seal" type="fixed">
		<parent link="seal"/>
		<child link="seal_corner_1"/>
		<origin rpy="-1.57 1.57 0" xyz="-0.1554 0.1105 0.005"/>
	</joint>
	<link name="seal_corner_2"/>
	<joint name="c2_to_seal" type="fixed">
		<parent link="seal"/>
		<child link="seal_corner_2"/>
		<origin rpy="-1.57 1.57 0" xyz="0.1654 0.1105 0.005"/>
	</joint>
	<link name="seal_corner_3"/>
	<joint name="c3_to_seal" type="fixed">
		<parent link="seal"/>
		<child link="seal_corner_3"/>
		<origin rpy="-1.57 1.57 0" xyz="0.1654 -0.1005 0.005"/>
	</joint>
	<link name="seal_corner_4"/>
	<joint name="c4_to_seal" type="fixed">
		<parent link="seal"/>
		<child link="seal_corner_4"/>
		<origin rpy="-1.57 1.57 0" xyz="-0.1554 -0.1005 0.005"/>
	</joint>
	<!-- Velcro section-->
	<link name="velcro">
		<!-- need to set all values -->
		<visual>
			<geometry>
				<box size="0.11 0.001 0.05"/>
			</geometry>
			<material name="Cyan">
				<color rgba="0.0 0.0 0.0 1.0"/>
			</material>
		</visual>
	</link>
	<joint name="velcro_to_frame_joint" type="fixed">
		<parent link="wood_frame"/>
		<child link="velcro"/>
		<origin rpy="0 0 0" xyz="-0.17535 0.015 0.2345"/>
	</joint>
	<!-- Door section-->
	<link name="door">
		<inertial>
			<origin rpy="0 0 0" xyz="0.0 0.0 0.0"/>
			<mass value="0.1"/>
			<inertia ixx="0.01" ixy="0.0" ixz="0.0" iyy="0.01" iyz="0.0" izz="0.01"/>
		</inertial>
		<visual>
			<origin rpy="1.5707963267948966 0 3.141592653589793" xyz="0 0 0.110"/>
			<geometry>
				<mesh filename="full/csm_outer_door.obj"/>
			</geometry>
			<material name="Gray">
				<color rgba="0.5 0.5 0.5 1.0"/>
			</material>
		</visual>
	</link>
	<joint name="door_to_frame_joint" type="revolute">
		<parent link="wood_frame"/>
		<child link="door"/>
		<origin rpy="0 0 0" xyz="0 0.0255 -0.113"/>
		<axis xyz="1 0 0"/>
		<limit effort="10" lower="-1.5707963267948966" upper="0" velocity="10"/>
	</joint>
	<!-- Latch housing section-->
	<link name="latch_housing">
		<inertial>
			<origin rpy="0 0 0" xyz="0.0 0.0 0.0"/>
			<mass value="0.1"/>
			<inertia ixx="0.01" ixy="0.0" ixz="0.0" iyy="0.01" iyz="0.0" izz="0.01"/>
		</inertial>
		<visual>
			<origin rpy="0 3.141592653589793 0" xyz="0 0 0"/>
			<geometry>
				<mesh filename="full/csm_latch_housing.obj"/>
			</geometry>
			<material name="Gray">
				<color rgba="0.5 0.5 0.5 1.0"/>
			</material>
		</visual>
	</link>
	<joint name="door_to_latch" type="fixed">
		<parent link="door"/>
		<child link="latch_housing"/>
		<origin rpy="0 0 0" xyz="0 0.0 0.233"/>
	</joint>
	<!-- Latch cover section-->
	<link name="latch_cover">
		<inertial>
			<origin rpy="0 0 0" xyz="0.0 0.0 0.0"/>
			<mass value="0.1"/>
			<inertia ixx="0.01" ixy="0.0" ixz="0.0" iyy="0.01" iyz="0.0" izz="0.01"/>
		</inertial>
		<visual>
			<origin rpy="0 0 0" xyz="0 0 0"/>
			<geometry>
				<mesh filename="full/csm_latch_cover.obj"/>
			</geometry>
			<material name="Gray">
				<color rgba="0.5 0.5 0.5 1.0"/>
			</material>
		</visual>
	</link>
	<joint name="housing_to_cover" type="fixed">
		<parent link="latch_housing"/>
		<child link="latch_cover"/>
		<origin rpy="0 0 0" xyz="0 0.012 0.0"/>
	</joint>
	<!-- Right latch pull section-->
	<link name="right_latch_pull">
		<inertial>
			<origin rpy="0 0 0" xyz="0.0 0.0 0.0"/>
			<mass value="0.1"/>
			<inertia ixx="0.01" ixy="0.0" ixz="0.0" iyy="0.01" iyz="0.0" izz="0.01"/>
		</inertial>
		<visual>
			<origin rpy="3.141592653589793 -1.5707963267948966 -1.5707963267948966" xyz="0 0 0"/>
			<geometry>
				<mesh filename="full/csm_latch_pull.obj"/>
			</geometry>
			<material name="Gray">
				<color rgba="0.5 0.5 0.5 1.0"/>
			</material>
		</visual>
	</link>
	<joint name="housing_to_right_latch_pull" type="prismatic">
		<parent link="latch_housing"/>
		<child link="right_latch_pull"/>
		<origin rpy="0 0 0" xyz="0.0258 0.01 -0.004"/>
		<axis xyz="1 0 0"/>
		<limit effort="10" lower="-0.0084" upper="0" velocity="10"/>
	</joint>
	<!-- Left latch pull section-->
	<link name="left_latch_pull">
		<inertial>
			<origin rpy="0 0 0" xyz="0.0 0.0 0.0"/>
			<mass value="0.1"/>
			<inertia ixx="0.01" ixy="0.0" ixz="0.0" iyy="0.01" iyz="0.0" izz="0.01"/>
		</inertial>
		<visual>
			<origin rpy="0 1.5707963267948966 -1.5707963267948966" xyz="0 0 0"/>
			<geometry>
				<mesh filename="full/csm_latch_pull.obj"/>
			</geometry>
			<material name="Gray">
				<color rgba="0.5 0.5 0.5 1.0"/>
			</material>
		</visual>
	</link>
	<joint name="housing_to_left_latch_pull" type="prismatic">
		<parent link="latch_housing"/>
		<child link="left_latch_pull"/>
		<origin rpy="0 0 0" xyz="-0.0258 0.01 -0.004"/>
		<axis xyz="1 0 0"/>
		<limit effort="10" lower="0" upper="0.0084" velocity="10"/>
	</joint>
	<!-- Latch lock section-->
	<link name="latch_lock">
		<inertial>
			<origin rpy="0 0 0" xyz="0.0 0.0 0.0"/>
			<mass value="0.1"/>
			<inertia ixx="0.01" ixy="0.0" ixz="0.0" iyy="0.01" iyz="0.0" izz="0.01"/>
		</inertial>
		<visual>
			<origin rpy="0 0 0" xyz="0 0.0012 -0.0084"/>
			<geometry>
				<mesh filename="full/csm_latch_lock.obj"/>
			</geometry>
			<material name="Gray">
				<color rgba="0.5 0.5 0.5 1.0"/>
			</material>
		</visual>
	</link>
	<joint name="housing_to_latch_lock" type="revolute">
		<parent link="latch_housing"/>
		<child link="latch_lock"/>
		<origin rpy="0 0 0" xyz="0 0.019 0.007"/>
		<axis xyz="1 0 0"/>
		<limit effort="10" lower="0" upper="1.5707963267948966" velocity="10"/>
	</joint>
	<!--TODO which handles are mounted?-->
	<!-- End Localization links/joints -->
	<joint name="lorge/hatch_frame_base_joint" type="fixed">
		<parent link="world"/>
		<child link="lorge/hatch_frame"/>
		<origin rpy="0 0 0" xyz="1.40208 -0.801983 -0.002"/>
	</joint>
	<link name="lorge/hatch_frame">
		<visual>
			<origin rpy="0 0 0" xyz="0.0 0.0 0.0"/>
			<geometry>
				<!-- <mesh filename="/home/er4-user/ws/install/hatch_accessories/share/hatch_accessories/meshes/visual/ivr_hatch_frame.stl"/> -->
				<mesh filename="decomposed/ivr_hatch_frame_no_left/ivr_hatch_frame_no_left.obj"/>
			</geometry>
			<material name="gray"/>
		</visual>
	</link>
	<joint name="lorge/hatch_frame_joint" type="fixed">
		<parent link="lorge/hatch_frame"/>
		<child link="lorge/hatch_bottom"/>
		<origin rpy="0 0 0" xyz="0.0 0.0 0.0"/>
	</joint>
	<link name="lorge/hatch_bottom">
		<!--TODO set proper inertia-->
		<inertial>
			<origin rpy="0 0 0" xyz="0.0 0.0 0.0"/>
			<mass value="0.1"/>
			<inertia ixx="0.1" ixy="0.0" ixz="0.0" iyy="0.1" iyz="0.0" izz="0.1"/>
		</inertial>
	</link>
	<joint name="lorge/hatch_bottom_back" type="fixed">
		<parent link="lorge/hatch_bottom"/>
		<child link="lorge/hatch_back"/>
		<origin rpy="0 0 0" xyz="0.0 0.0 0.0"/>
	</joint>
	<link name="lorge/hatch_back">
	</link>
	<joint name="lorge/hatch_bottom_front" type="fixed">
		<parent link="lorge/hatch_bottom"/>
		<child link="lorge/hatch_front"/>
		<origin rpy="0 0 0" xyz="0.578 0.0 0.0"/>
	</joint>
	<link name="lorge/hatch_front">
	</link>
	<joint name="lorge/hatch_frame_front_bottom_joint" type="fixed">
		<parent link="lorge/hatch_frame"/>
		<child link="lorge/hatch_frame_front_bottom"/>
		<origin rpy="0 0 0" xyz="0.67 0.0 0.0"/>
	</joint>
	<link name="lorge/hatch_frame_front_bottom"/>
	<joint name="lorge/hatch_bottom_left" type="fixed">
		<parent link="lorge/hatch_bottom"/>
		<child link="lorge/hatch_left"/>
		<origin rpy="0 0 0" xyz="0.0 -0.01 0.0"/>
	</joint>
	<link name="lorge/hatch_left">
	</link>
	<joint name="lorge/hatch_bottom_right" type="fixed">
		<parent link="lorge/hatch_bottom"/>
		<child link="lorge/hatch_right"/>
		<origin rpy="0 0 0" xyz="0.0 1.22 0.0"/>
	</joint>
	<link name="lorge/hatch_right">
	</link>
	<joint name="lorge/hatch_bottom_top" type="fixed">
		<parent link="lorge/hatch_bottom"/>
		<child link="lorge/hatch_top"/>
		<origin rpy="0 0 0" xyz="0.589 0.0 1.913"/>
	</joint>
	<link name="lorge/hatch_top">
	</link>
	<joint name="lorge/hatch_frame_front_top_joint" type="fixed">
		<parent link="lorge/hatch_frame"/>
		<child link="lorge/hatch_frame_front_top"/>
		<origin rpy="0 0 0" xyz="0.67 0.0 2.111"/>
	</joint>
	<link name="lorge/hatch_frame_front_top"/>
	<!--This is for when there is a bench at the level of the bottom of the hatch opening.-->
	<!-- TODO add if statement -->
	<joint name="lorge/hatch_frame_bench_joint" type="fixed">
		<parent link="lorge/hatch_frame"/>
		<child link="lorge/hatch_bench"/>
		<origin rpy="0 0 0" xyz="0.0 0.0 0.0"/>
	</joint>
	<link name="lorge/hatch_bench">
		<visual>
			<origin rpy="0 0 0" xyz="0.3375 0.6535 0.25765"/>
			<geometry>
				<box size="0.675 1.307 0.4953"/>
			</geometry>
			<material name="gray"/>
		</visual>
	</link>
	<joint name="lorge/hatch_inner_frame_joint" type="fixed">
		<parent link="lorge/hatch_frame"/>
		<child link="lorge/hatch_inner_frame"/>
		<origin rpy="0 0 3.141592653589793" xyz="0.584329 1.245 0.7113"/>
	</joint>
	<link name="lorge/hatch_inner_frame">
		<!--TODO set proper inertia-->
		<inertial>
			<origin rpy="0 0 0" xyz="0.01151002 0.5753364 0.5459604"/>
			<mass value="7.381808"/>
			<inertia ixx="4.347317" ixy="-0.001737663" ixz="0.00003731045" iyy="2.49037" iyz="0.02113006" izz="1.858204"/>
		</inertial>
		<visual>
			<origin rpy="0 0 0" xyz="0.0 0.0 0.0"/>
			<geometry>
				<mesh filename="decomposed/hatch_4060_frame/hatch_4060_frame.obj"/>
			</geometry>
			<material name="gray"/>
		</visual>
	</link>
	<joint name="lorge/hatch_outer_frame_joint" type="fixed">
		<parent link="lorge/hatch_frame"/>
		<child link="lorge/hatch_outer_frame"/>
		<origin rpy="0 0 0" xyz="0.678 0.057 0.716"/>
	</joint>
	<link name="lorge/hatch_outer_frame">
		<!--TODO set proper inertia-->
		<inertial>
			<origin rpy="0 0 0" xyz="0.01151002 0.5753364 0.5459604"/>
			<mass value="7.381808"/>
			<inertia ixx="4.347317" ixy="-0.001737663" ixz="0.00003731045" iyy="2.49037" iyz="0.02113006" izz="1.858204"/>
		</inertial>
		<visual>
			<origin rpy="0 0 0" xyz="0.0 0.0 0.0"/>
			<geometry>
				<mesh filename="decomposed/hatch_4060_frame/hatch_4060_frame.obj"/>
			</geometry>
			<material name="gray"/>
		</visual>
	</link>
	<joint name="lorge/hatch_outer_frame_face_joint" type="revolute">
		<axis xyz="0 0 1"/>
		<limit effort="10.0" lower="0.0" upper="1.65806" velocity="0.5"/>
		<!-- 95 degrees -->
		<parent link="lorge/hatch_outer_frame"/>
		<child link="lorge/hatch_face"/>
		<origin rpy="0 0 0" xyz="0.0827 1.21379 0.0457"/>
		<dynamics damping="3.0" friction="3.0"/>
	</joint>
	<link name="lorge/hatch_face">
		<!--TODO set proper inertia-->
		<inertial>
			<origin rpy="0 0 0" xyz="-0.05635759 -0.6185068 0.5223265"/>
			<mass value="18.65315"/>
			<inertia ixx="5.956354" ixy="-0.02180356" ixz="0.001603986" iyy="3.823124" iyz="-0.06191432" izz="2.152308"/>
		</inertial>
		<!--TODO check the orientation of the hinges, up or down-->
		<visual>
			<origin rpy="0 0 0" xyz="0.0 0.0 0.0"/>
			<geometry>
				<mesh filename="decomposed/simplified_hatch_4060_face/simplified_hatch_4060_face.obj"/>
			</geometry>
			<material name="gray"/>
		</visual>
	</link>
	<joint name="lorge/right_cal_1_joint" type="fixed">
		<parent link="lorge/hatch_face"/>
		<child link="lorge/right_cal_1_frame"/>
		<origin rpy="0 0 0" xyz="0.0167 0.0 0.0"/>
	</joint>
	<link name="lorge/right_cal_1_frame"/>
	<joint name="lorge/right_cal_2_joint" type="fixed">
		<parent link="lorge/hatch_face"/>
		<child link="lorge/right_cal_2_frame"/>
		<origin rpy="0 0 0" xyz="0.0 0.0167 0.0"/>
	</joint>
	<link name="lorge/right_cal_2_frame"/>
	<joint name="lorge/external_rotary_joint" type="revolute">
		<axis xyz="0 0 1"/>
		<!--This is continuously rotatable-->
		<limit effort="10.0" lower="0.0" upper="6.28" velocity="0.5"/>
		<parent link="lorge/hatch_face"/>
		<child link="lorge/external_rotary_wheel"/>
		<origin rpy="0 -1.5707963267948966 0" xyz="-0.17161 -0.9474 0.4325"/>
		<dynamics damping="3.0" friction="3.0"/>
	</joint>
	<link name="lorge/external_rotary_wheel">
		<!--TODO set proper inertia-->
		<inertial>
			<origin rpy="0 0 0" xyz="-0.000002016828 0.000002604043 0.0124263"/>
			<mass value="0.4130986"/>
			<inertia ixx="0.0005752646" ixy="-0.0000006009927" ixz="0.000000006697924" iyy="0.0005474983" iyz="-0.000000007626402" izz="0.001016091"/>
		</inertial>
		<visual>
			<origin rpy="0 0 0" xyz="0.0 0.0 0.0"/>
			<geometry>
				<mesh filename="full/crank_wheel.obj"/>
			</geometry>
			<material name="blue"/>
		</visual>
	</link>
	<joint name="lorge/external_rotary_handle_joint" type="revolute">
		<axis xyz="1 0 0"/>
		<!--This is continuously rotatable-->
		<limit effort="10.0" lower="0.0" upper="1.57" velocity="0.5"/>
		<parent link="lorge/external_rotary_wheel"/>
		<child link="lorge/external_rotary_handle"/>
		<origin rpy="0 0 0" xyz="0.0 0.053975 0.0155"/>
		<dynamics damping="3.0" friction="3.0"/>
	</joint>
	<link name="lorge/external_rotary_handle">
		<!--TODO set proper inertia-->
		<inertial>
			<origin rpy="0 0 0" xyz="0.0 0.0 0.0338876"/>
			<mass value="0.03289431"/>
			<inertia ixx="0.00001133204" ixy="-0.0000000002536241" ixz="-0.00000000002353435" iyy="0.00001133386" iyz="-0.00000000002134657" izz="0.0000009871989"/>
		</inertial>
		<visual>
			<origin rpy="0 0 0" xyz="0.0 0.0 0.00355"/>
			<geometry>
				<mesh filename="full/crank_handle.obj"/>
			</geometry>
			<material name="blue"/>
		</visual>
	</link>
	<joint name="lorge/external_rotary_handle_grasp_joint" type="fixed">
		<parent link="lorge/external_rotary_handle"/>
		<child link="lorge/external_rotary_handle_grasp"/>
		<origin rpy="0 0 0" xyz="0.0 0.0 0.04"/>
	</joint>
	<link name="lorge/external_rotary_handle_grasp"/>
	<joint name="lorge/internal_rotary_joint" type="revolute">
		<axis xyz="0 0 1"/>
		<!--This is continuously rotatable-->
		<limit effort="10.0" lower="0.0" upper="6.28" velocity="0.5"/>
		<parent link="lorge/hatch_face"/>
		<child link="lorge/internal_rotary_wheel"/>
		<origin rpy="0 1.5707963267948966 0" xyz="0.04431 -0.9474 0.4265"/>
		<dynamics damping="3.0" friction="3.0"/>
	</joint>
	<link name="lorge/internal_rotary_wheel">
		<!--TODO set proper inertia-->
		<inertial>
			<origin rpy="0 0 0" xyz="-0.000002016828 0.000002604043 0.0124263"/>
			<mass value="0.4130986"/>
			<inertia ixx="0.0005752646" ixy="-0.0000006009927" ixz="0.000000006697924" iyy="0.0005474983" iyz="-0.000000007626402" izz="0.001016091"/>
		</inertial>
		<visual>
			<origin rpy="0 0 0" xyz="0.0 0.0 0.0"/>
			<geometry>
				<mesh filename="full/crank_wheel.obj"/>
			</geometry>
			<material name="blue"/>
		</visual>
	</link>
	<joint name="lorge/internal_rotary_handle_joint" type="revolute">
		<axis xyz="1 0 0"/>
		<!--This is continuously rotatable-->
		<limit effort="10.0" lower="0.0" upper="1.57" velocity="0.5"/>
		<parent link="lorge/internal_rotary_wheel"/>
		<child link="lorge/internal_rotary_handle"/>
		<origin rpy="0 0 0" xyz="0.0 0.053975 0.0155"/>
		<dynamics damping="3.0" friction="3.0"/>
	</joint>
	<link name="lorge/internal_rotary_handle">
		<!--TODO set proper inertia-->
		<inertial>
			<origin rpy="0 0 0" xyz="0.0 0.0 0.0338876"/>
			<mass value="0.03289431"/>
			<inertia ixx="0.00001133204" ixy="-0.0000000002536241" ixz="-0.00000000002353435" iyy="0.00001133386" iyz="-0.00000000002134657" izz="0.0000009871989"/>
		</inertial>
		<visual>
			<origin rpy="0 0 0" xyz="0.0 0.0 0.00355"/>
			<geometry>
				<mesh filename="full/crank_handle.obj"/>
			</geometry>
			<material name="blue"/>
		</visual>
	</link>
	<joint name="lorge/internal_rotary_handle_grasp_joint" type="fixed">
		<parent link="lorge/internal_rotary_handle"/>
		<child link="lorge/internal_rotary_handle_grasp"/>
		<origin rpy="0 0 0" xyz="0.0 0.0 0.04"/>
	</joint>
	<link name="lorge/internal_rotary_handle_grasp"/>
	<joint name="lorge/external_1_grab_handle_joint" type="fixed">
		<parent link="lorge/hatch_face"/>
		<child link="lorge/external_1_grab_handle"/>
		<origin rpy="0 3.141592653589793 0" xyz="-0.07 -0.9016 0.8021"/>
	</joint>
	<link name="lorge/external_1_grab_handle">
		<!--TODO set proper inertia-->
		<inertial>
			<origin rpy="0 0 0" xyz="0.06460542 -0.08890724 0.0"/>
			<mass value="0.1558987"/>
			<inertia ixx="0.0008422355" ixy="0.00000001340204" ixz="0.000000002477554" iyy="0.0001004532" iyz="0.00000006036754" izz="0.0009303066"/>
		</inertial>
		<visual>
			<!--This transform is for the stl file origin-->
			<origin rpy="0 0 0" xyz="0.0 0.0 0.0"/>
			<geometry>
				<mesh filename="decomposed/grab_handle/grab_handle.obj"/>
			</geometry>
			<material name="blue"/>
		</visual>
	</link>
	<joint name="lorge/external_1_grab_center_joint" type="fixed">
		<parent link="lorge/external_1_grab_handle"/>
		<child link="lorge/external_1_grab_center"/>
		<origin rpy="0 0 0" xyz="0.0807 -0.0889 0.0"/>
	</joint>
	<link name="lorge/external_1_grab_center"/>
	<joint name="lorge/external_1_grab_touch_joint" type="fixed">
		<parent link="lorge/external_1_grab_handle"/>
		<child link="lorge/external_1_grab_touch"/>
		<origin rpy="0 0 0" xyz="0.0934 -0.0889 0.0"/>
	</joint>
	<link name="lorge/external_1_grab_touch"/>
	<joint name="lorge/external_2_grab_handle_joint" type="fixed">
		<parent link="lorge/hatch_face"/>
		<child link="lorge/external_2_grab_handle"/>
		<origin rpy="-1.5707963267948966 3.141592653589793 0" xyz="-0.07 -1.0272999999999999 0.6887"/>
	</joint>
	<link name="lorge/external_2_grab_handle">
		<!--TODO set proper inertia-->
		<inertial>
			<origin rpy="0 0 0" xyz="0.06460542 -0.08890724 0.0"/>
			<mass value="0.1558987"/>
			<inertia ixx="0.0008422355" ixy="0.00000001340204" ixz="0.000000002477554" iyy="0.0001004532" iyz="0.00000006036754" izz="0.0009303066"/>
		</inertial>
		<visual>
			<!--This transform is for the stl file origin-->
			<origin rpy="0 0 0" xyz="0.0 0.0 0.0"/>
			<geometry>
				<mesh filename="decomposed/grab_handle/grab_handle.obj"/>
			</geometry>
			<material name="blue"/>
		</visual>
	</link>
	<joint name="lorge/external_2_grab_center_joint" type="fixed">
		<parent link="lorge/external_2_grab_handle"/>
		<child link="lorge/external_2_grab_center"/>
		<origin rpy="0 0 0" xyz="0.0807 -0.0889 0.0"/>
	</joint>
	<link name="lorge/external_2_grab_center"/>
	<joint name="lorge/external_2_grab_touch_joint" type="fixed">
		<parent link="lorge/external_2_grab_handle"/>
		<child link="lorge/external_2_grab_touch"/>
		<origin rpy="0 0 0" xyz="0.0934 -0.0889 0.0"/>
	</joint>
	<link name="lorge/external_2_grab_touch"/>
	<joint name="lorge/external_3_grab_handle_joint" type="fixed">
		<parent link="lorge/hatch_face"/>
		<child link="lorge/external_3_grab_handle"/>
		<origin rpy="-1.5707963267948966 3.141592653589793 0" xyz="-0.07 -0.1295 0.6957"/>
	</joint>
	<link name="lorge/external_3_grab_handle">
		<!--TODO set proper inertia-->
		<inertial>
			<origin rpy="0 0 0" xyz="0.06460542 -0.08890724 0.0"/>
			<mass value="0.1558987"/>
			<inertia ixx="0.0008422355" ixy="0.00000001340204" ixz="0.000000002477554" iyy="0.0001004532" iyz="0.00000006036754" izz="0.0009303066"/>
		</inertial>
		<visual>
			<!--This transform is for the stl file origin-->
			<origin rpy="0 0 0" xyz="0.0 0.0 0.0"/>
			<geometry>
				<mesh filename="decomposed/grab_handle/grab_handle.obj"/>
			</geometry>
			<material name="blue"/>
		</visual>
	</link>
	<joint name="lorge/external_3_grab_center_joint" type="fixed">
		<parent link="lorge/external_3_grab_handle"/>
		<child link="lorge/external_3_grab_center"/>
		<origin rpy="0 0 0" xyz="0.0807 -0.0889 0.0"/>
	</joint>
	<link name="lorge/external_3_grab_center"/>
	<joint name="lorge/external_3_grab_touch_joint" type="fixed">
		<parent link="lorge/external_3_grab_handle"/>
		<child link="lorge/external_3_grab_touch"/>
		<origin rpy="0 0 0" xyz="0.0934 -0.0889 0.0"/>
	</joint>
	<link name="lorge/external_3_grab_touch"/>
	<joint name="lorge/internal_2_grab_handle_joint" type="fixed">
		<parent link="lorge/hatch_face"/>
		<child link="lorge/internal_2_grab_handle"/>
		<origin rpy="1.5707963267948966 0 0" xyz="-0.058 -1.078 0.6957"/>
	</joint>
	<link name="lorge/internal_2_grab_handle">
		<!--TODO set proper inertia-->
		<inertial>
			<origin rpy="0 0 0" xyz="0.06460542 -0.08890724 0.0"/>
			<mass value="0.1558987"/>
			<inertia ixx="0.0008422355" ixy="0.00000001340204" ixz="0.000000002477554" iyy="0.0001004532" iyz="0.00000006036754" izz="0.0009303066"/>
		</inertial>
		<visual>
			<!--This transform is for the stl file origin-->
			<origin rpy="0 0 0" xyz="0.0 0.0 0.0"/>
			<geometry>
				<mesh filename="decomposed/grab_handle/grab_handle.obj"/>
			</geometry>
			<material name="blue"/>
		</visual>
	</link>
	<joint name="lorge/internal_2_grab_center_joint" type="fixed">
		<parent link="lorge/internal_2_grab_handle"/>
		<child link="lorge/internal_2_grab_center"/>
		<origin rpy="0 0 0" xyz="0.0807 -0.0889 0.0"/>
	</joint>
	<link name="lorge/internal_2_grab_center"/>
	<joint name="lorge/internal_2_grab_touch_joint" type="fixed">
		<parent link="lorge/internal_2_grab_handle"/>
		<child link="lorge/internal_2_grab_touch"/>
		<origin rpy="0 0 0" xyz="0.0934 -0.0889 0.0"/>
	</joint>
	<link name="lorge/internal_2_grab_touch"/>
	<!-- Trainer -->
	<!-- End Localization links/joints -->
	<joint name="trainer_frame_base_joint" type="fixed">
		<parent link="world"/>
		<child link="trainer_frame"/>
		<origin rpy="0 0 4.7112" xyz="-2.0992 2.4346 0.0"/>
	</joint>
	<link name="trainer_frame">
		<visual>
			<!--Offset is to adjust for the radius on the extrusion-->
			<origin rpy="0 0 0" xyz="0.0 0.004 0.0"/>
			<geometry>
				<mesh filename="full/ivr_tasktrainer_frame.obj"/>
			</geometry>
			<material name="gray"/>
		</visual>
	</link>
	<joint name="trainer_box_joint" type="fixed">
		<parent link="trainer_frame"/>
		<child link="trainer_box"/>
		<origin rpy="0 0 0" xyz="0.0 0.0 0.0"/>
	</joint>
	<link name="trainer_box">
		<!--TODO set proper inertia-->
		<inertial>
			<origin rpy="0 0 0" xyz="0.0 0.0 0.0"/>
			<mass value="0.1"/>
			<inertia ixx="0.1" ixy="0.0" ixz="0.0" iyy="0.1" iyz="0.0" izz="0.1"/>
		</inertial>
	</link>
	<joint name="trainer_top_joint" type="fixed">
		<parent link="trainer_frame"/>
		<child link="trainer_top"/>
		<origin rpy="0 0 0" xyz="0.0 0.0 1.52"/>
	</joint>
	<link name="trainer_top">
	</link>
	<joint name="trainer_plane_left_joint" type="fixed">
		<parent link="trainer_frame"/>
		<child link="trainer_plane_left"/>
		<origin rpy="0 0 0" xyz="0.0 0.0 0.0"/>
	</joint>
	<link name="trainer_plane_left">
	</link>
	<joint name="trainer_plane_middle_joint" type="fixed">
		<parent link="trainer_frame"/>
		<child link="trainer_plane_middle"/>
		<origin rpy="0 0 0" xyz="0.0 0.42 0.0"/>
	</joint>
	<link name="trainer_plane_middle">
	</link>
	<joint name="trainer_plane_right_1_joint" type="fixed">
		<parent link="trainer_frame"/>
		<child link="trainer_plane_right_1"/>
		<origin rpy="0 0 0" xyz="0.0 0.8 0.0"/>
	</joint>
	<link name="trainer_plane_right_1">
	</link>
	<joint name="trainer_plane_right_2_joint" type="fixed">
		<parent link="trainer_frame"/>
		<child link="trainer_plane_right_2"/>
		<origin rpy="0 0 0" xyz="1.124 0.81 0.0"/>
	</joint>
	<link name="trainer_plane_right_2">
	</link>
	<joint name="bench_base_joint" type="fixed">
		<parent link="trainer_frame"/>
		<child link="bench_back"/>
		<origin rpy="0 0 0" xyz="1.261 0 0.4769"/>
	</joint>
	<link name="bench_back">
		<!--TODO set proper inertia-->
		<inertial>
			<origin rpy="0 0 0" xyz="0.064 0.448 0.02"/>
			<mass value="12.32218"/>
			<inertia ixx="0.8241741" ixy="0.0" ixz="0.0" iyy="0.01820499" iyz="0.0" izz="0.8390932"/>
		</inertial>
		<visual>
			<origin rpy="0 0 0" xyz="0.0635 0.4475 0.02"/>
			<geometry>
				<box size="0.127 0.895 0.04"/>
			</geometry>
			<material name="gray"/>
		</visual>
	</link>
	<joint name="bench_left_joint" type="fixed">
		<parent link="bench_back"/>
		<child link="bench_left"/>
		<origin rpy="0 0 0" xyz="0.0 0.0 0.0"/>
	</joint>
	<link name="bench_left">
		<inertial>
			<origin rpy="0 0 0" xyz="0.354 0.02 0.02"/>
			<mass value="3.070111"/>
			<inertia ixx="0.0008186962" ixy="0.0" ixz="0.0" iyy="0.128654" iyz="0.0" izz="0.128654"/>
		</inertial>
		<visual>
			<origin rpy="0 0 0" xyz="0.354 0.02 0.02"/>
			<geometry>
				<box size="0.708 0.04 0.04"/>
			</geometry>
			<material name="gray"/>
		</visual>
	</link>
	<joint name="bench_right_joint" type="fixed">
		<parent link="bench_back"/>
		<child link="bench_right"/>
		<origin rpy="0 0 0" xyz="0.0 0.84535 0.0"/>
	</joint>
	<link name="bench_right">
		<inertial>
			<origin rpy="0 0 0" xyz="0.354 0.02 0.02"/>
			<mass value="3.070111"/>
			<inertia ixx="0.0008186962" ixy="0.0" ixz="0.0" iyy="0.128654" iyz="0.0" izz="0.128654"/>
		</inertial>
		<visual>
			<origin rpy="0 0 0" xyz="0.354 0.025 0.02"/>
			<geometry>
				<box size="0.708 0.04 0.04"/>
			</geometry>
			<material name="gray"/>
		</visual>
	</link>
	<joint name="bench_front_joint" type="fixed">
		<parent link="bench_back"/>
		<child link="bench_front"/>
		<origin rpy="0 0 0" xyz="0.6612 0.0 0.0"/>
	</joint>
	<link name="bench_front">
		<inertial>
			<origin rpy="0 0 0" xyz="0.02 0.448 0.02"/>
			<mass value="3.881002"/>
			<inertia ixx="0.2595824" ixy="0.0" ixz="0.0" iyy="0.001034934" iyz="0.0" izz="0.2595824"/>
		</inertial>
		<visual>
			<origin rpy="0 0 0" xyz="0.025 0.4475 0.02"/>
			<geometry>
				<box size="0.04 0.895 0.04"/>
			</geometry>
			<material name="gray"/>
		</visual>
	</link>
	<joint name="bench_lid_joint" type="revolute">
		<axis xyz="0 -1 0"/>
		<!-- upper is 95 degrees -->
		<limit effort="10.0" lower="0.0" upper="1.65806" velocity="0.5"/>
		<parent link="bench_back"/>
		<child link="bench_lid"/>
		<origin rpy="0 0 0" xyz="0.127 0.0 0.0475"/>
		<dynamics damping="3.0" friction="3.0"/>
	</joint>
	<link name="bench_lid">
		<!--TODO set proper inertia-->
		<inertial>
			<origin rpy="0 0 0" xyz="0.2652256 0.46 0.03190335"/>
			<mass value="9.07185"/>
			<inertia ixx="0.643167" ixy="0.0" ixz="0.002867943" iyy="0.2210995" iyz="0.0" izz="0.8576681"/>
		</inertial>
		<visual>
			<origin rpy="0 0 0" xyz="0.0 0.0 0.0"/>
			<geometry>
				<mesh filename="decomposed/bench_lid/bench_lid.obj"/>
			</geometry>
			<material name="blue"/>
		</visual>
	</link>
	<joint name="bench_left_cal_joint" type="fixed">
		<parent link="bench_front"/>
		<child link="bench_left_cal_frame"/>
		<origin rpy="0 0 0" xyz="0.045 0.0 0.0"/>
	</joint>
	<link name="bench_left_cal_frame"/>
	<joint name="bench_right_cal_joint" type="fixed">
		<parent link="bench_right"/>
		<child link="bench_right_cal_frame"/>
		<origin rpy="0 0 0" xyz="0.7062 0.05 0.0"/>
	</joint>
	<link name="bench_right_cal_frame"/>
	<joint name="trainer_front_left_face_joint" type="fixed">
		<parent link="trainer_frame"/>
		<child link="front_left_face"/>
		<origin rpy="0 0 0" xyz="1.25 0.08 0.457"/>
	</joint>
	<link name="front_left_face">
		<!--TODO set proper inertia-->
		<inertial>
			<origin rpy="0 0 0" xyz="0.0 0.0 0.0"/>
			<mass value="0.1"/>
			<inertia ixx="0.1" ixy="0.0" ixz="0.0" iyy="0.1" iyz="0.0" izz="0.1"/>
		</inertial>
		<visual>
			<origin rpy="0 0 0" xyz="0.0 0.0 0.0"/>
			<geometry>
				<mesh filename="full/front_left_face.obj"/>
			</geometry>
			<material name="gray"/>
		</visual>
	</link>
	<joint name="cubby_1_joint" type="fixed">
		<parent link="front_left_face"/>
		<child link="cubby_1"/>
		<origin rpy="0 0 0" xyz="0.0 0.0 0.525"/>
	</joint>
	<link name="cubby_1">
		<!--TODO set proper inertia-->
		<inertial>
			<origin rpy="0 0 0" xyz="0.0 0.0 0.0"/>
			<mass value="0.1"/>
			<inertia ixx="0.1" ixy="0.0" ixz="0.0" iyy="0.1" iyz="0.0" izz="0.1"/>
		</inertial>
		<visual>
			<origin rpy="0 0 0" xyz="0.0 0.0 0.0"/>
			<geometry>
				<mesh filename="full/cubby_1.obj"/>
			</geometry>
			<material name="gray"/>
		</visual>
	</link>
	<joint name="cubby_2_joint" type="fixed">
		<parent link="front_left_face"/>
		<child link="cubby_2"/>
		<origin rpy="0 0 0" xyz="0.0 0.0 0.875"/>
	</joint>
	<link name="cubby_2">
		<!--TODO set proper inertia-->
		<inertial>
			<origin rpy="0 0 0" xyz="0.0 0.0 0.0"/>
			<mass value="0.1"/>
			<inertia ixx="0.1" ixy="0.0" ixz="0.0" iyy="0.1" iyz="0.0" izz="0.1"/>
		</inertial>
		<visual>
			<origin rpy="0 0 0" xyz="0.0 0.0 0.0"/>
			<geometry>
				<mesh filename="full/cubby_2.obj"/>
			</geometry>
			<material name="gray"/>
		</visual>
	</link>
	<joint name="trainer_front_right_face_joint" type="fixed">
		<parent link="trainer_frame"/>
		<child link="front_right_face"/>
		<origin rpy="0 0 0" xyz="1.25 0.465 0.457"/>
	</joint>
	<link name="front_right_face">
		<!--TODO set proper inertia-->
		<inertial>
			<origin rpy="0 0 0" xyz="0.0 0.0 0.0"/>
			<mass value="0.1"/>
			<inertia ixx="0.1" ixy="0.0" ixz="0.0" iyy="0.1" iyz="0.0" izz="0.1"/>
		</inertial>
		<visual>
			<origin rpy="0 0 0" xyz="0.0 0.0 0.0"/>
			<geometry>
				<mesh filename="full/front_right_face.obj"/>
			</geometry>
			<material name="gray"/>
		</visual>
	</link>
	<joint name="cabinet_1_joint" type="revolute">
		<axis xyz="0 0 1"/>
		<limit effort="10.0" lower="0.0" upper="3.14" velocity="0.5"/>
		<parent link="front_right_face"/>
		<child link="cabinet_1"/>
		<origin rpy="0 0 0" xyz="0.017 0.3458 0.713"/>
		<dynamics damping="3.0" friction="3.0"/>
	</joint>
	<link name="cabinet_1">
		<!--TODO set proper inertia-->
		<inertial>
			<origin rpy="0 0 0" xyz="0.0 0.0 0.0"/>
			<mass value="0.1"/>
			<inertia ixx="0.1" ixy="0.0" ixz="0.0" iyy="0.1" iyz="0.0" izz="0.1"/>
		</inertial>
		<visual>
			<origin rpy="0 0 0" xyz="-0.010675 -0.00366 0.0"/>
			<geometry>
				<mesh filename="full/cabinet_door_1.obj"/>
			</geometry>
			<material name="blue"/>
		</visual>
	</link>
	<joint name="round_latch_housing_joint" type="fixed">
		<parent link="cabinet_1"/>
		<child link="round_latch_housing"/>
		<origin rpy="3.141592653589793 0 0" xyz="-0.00547 -0.28855 0.16622"/>
	</joint>
	<link name="round_latch_housing">
		<!--TODO set proper inertia-->
		<inertial>
			<origin rpy="0 0 0" xyz="0.0 0.0 0.0"/>
			<mass value="0.1"/>
			<inertia ixx="0.1" ixy="0.0" ixz="0.0" iyy="0.1" iyz="0.0" izz="0.1"/>
		</inertial>
		<visual>
			<origin rpy="0 0 0" xyz="0.0 0.0 0.0"/>
			<geometry>
				<mesh filename="full/round_latch_housing.obj"/>
			</geometry>
			<material name="gray"/>
		</visual>
	</link>
	<joint name="round_latch_joint" type="revolute">
		<axis xyz="0 0 -1"/>
		<limit effort="10.0" lower="0.0" upper="3.14" velocity="0.5"/>
		<parent link="round_latch_housing"/>
		<child link="round_latch_handle"/>
		<origin rpy="0 0 0" xyz="0.0 -0.0212 -0.0035"/>
		<dynamics damping="3.0" friction="3.0"/>
	</joint>
	<link name="round_latch_handle">
		<!--TODO set proper inertia-->
		<inertial>
			<origin rpy="0 0 0" xyz="0.0 0.0 0.0"/>
			<mass value="0.1"/>
			<inertia ixx="0.1" ixy="0.0" ixz="0.0" iyy="0.1" iyz="0.0" izz="0.1"/>
		</inertial>
		<visual>
			<origin rpy="0 0 0" xyz="0.0 0.0 0.0"/>
			<geometry>
				<mesh filename="full/round_latch_handle.obj"/>
			</geometry>
			<material name="blue"/>
		</visual>
	</link>
	<joint name="cabinet_2_joint" type="revolute">
		<axis xyz="0 0 -1"/>
		<limit effort="10.0" lower="0.0" upper="3.14" velocity="0.5"/>
		<parent link="front_right_face"/>
		<child link="cabinet_2"/>
		<origin rpy="0 0 0" xyz="0.017 -0.0018 0.379"/>
		<dynamics damping="3.0" friction="3.0"/>
	</joint>
	<link name="cabinet_2">
		<!--TODO set proper inertia-->
		<inertial>
			<origin rpy="0 0 0" xyz="0.0 0.0 0.0"/>
			<mass value="0.1"/>
			<inertia ixx="0.1" ixy="0.0" ixz="0.0" iyy="0.1" iyz="0.0" izz="0.1"/>
		</inertial>
		<visual>
			<origin rpy="0 0 0" xyz="-0.010675 0.00366 0.0"/>
			<geometry>
				<mesh filename="full/cabinet_door_2.obj"/>
			</geometry>
			<material name="blue"/>
		</visual>
	</link>
	<joint name="push_latch_housing_joint" type="fixed">
		<parent link="cabinet_2"/>
		<child link="push_latch_housing"/>
		<origin rpy="0 0 0" xyz="-0.0075 0.2185 0.134"/>
	</joint>
	<link name="push_latch_housing">
		<!--TODO set proper inertia-->
		<inertial>
			<origin rpy="0 0 0" xyz="0.0 0.0 0.0"/>
			<mass value="0.1"/>
			<inertia ixx="0.1" ixy="0.0" ixz="0.0" iyy="0.1" iyz="0.0" izz="0.1"/>
		</inertial>
		<visual>
			<origin rpy="0 0 0" xyz="0.0 0.0 0.0"/>
			<geometry>
				<mesh filename="full/push_latch_housing.obj"/>
			</geometry>
			<material name="gray"/>
		</visual>
	</link>
	<joint name="push_latch_button_joint" type="prismatic">
		<axis xyz="-1 0 0"/>
		<!--TODO button travel is a complete guess at this point-->
		<limit effort="10.0" lower="0.0" upper="0.005" velocity="0.5"/>
		<parent link="push_latch_housing"/>
		<child link="push_latch_button"/>
		<origin rpy="0 0 0.39269908169872414" xyz="-0.0125 0.0285 0.0045"/>
		<dynamics damping="3.0" friction="3.0"/>
	</joint>
	<link name="push_latch_button">
		<!--TODO set proper inertia-->
		<inertial>
			<origin rpy="0 0 0" xyz="0.0 0.0 0.0"/>
			<mass value="0.1"/>
			<inertia ixx="0.1" ixy="0.0" ixz="0.0" iyy="0.1" iyz="0.0" izz="0.1"/>
		</inertial>
		<visual>
			<origin rpy="0 0 0" xyz="0.0 0.0 0.0"/>
			<geometry>
				<mesh filename="full/push_latch_button.obj"/>
			</geometry>
			<material name="blue"/>
		</visual>
	</link>
	<joint name="push_latch_handle_joint" type="revolute">
		<axis xyz="0 0 1"/>
		<limit effort="10.0" lower="0.0" upper="1.0471975511965976" velocity="0.5"/>
		<parent link="push_latch_housing"/>
		<child link="push_latch_handle"/>
		<origin rpy="0 0 0" xyz="-0.003 0.079 0.0045"/>
		<dynamics damping="3.0" friction="3.0"/>
	</joint>
	<link name="push_latch_handle">
		<!--TODO set proper inertia-->
		<inertial>
			<origin rpy="0 0 0" xyz="0.0 0.0 0.0"/>
			<mass value="0.1"/>
			<inertia ixx="0.1" ixy="0.0" ixz="0.0" iyy="0.1" iyz="0.0" izz="0.1"/>
		</inertial>
		<visual>
			<origin rpy="0 0 0" xyz="0.0 0.0 0.0"/>
			<geometry>
				<mesh filename="full/push_latch_handle.obj"/>
			</geometry>
			<material name="blue"/>
		</visual>
	</link>
	<joint name="cabinet_3_joint" type="revolute">
		<axis xyz="0 0 1"/>
		<limit effort="10.0" lower="0.0" upper="3.141592653589793" velocity="0.5"/>
		<parent link="front_right_face"/>
		<child link="cabinet_3"/>
		<origin rpy="0 0 0" xyz="0.017 0.3458 0.007"/>
		<dynamics damping="3.0" friction="3.0"/>
	</joint>
	<link name="cabinet_3">
		<!--TODO set proper inertia-->
		<inertial>
			<origin rpy="0 0 0" xyz="0.0 0.0 0.0"/>
			<mass value="0.1"/>
			<inertia ixx="0.1" ixy="0.0" ixz="0.0" iyy="0.1" iyz="0.0" izz="0.1"/>
		</inertial>
		<visual>
			<origin rpy="0 0 0" xyz="-0.010675 -0.00366 0.0"/>
			<geometry>
				<mesh filename="full/cabinet_door_3.obj"/>
			</geometry>
			<material name="blue"/>
		</visual>
	</link>
	<joint name="trainer_side_face_base_joint" type="fixed">
		<parent link="trainer_frame"/>
		<child link="side_bottom_face"/>
		<origin rpy="0 0 0" xyz="0.812 0.887 0.04"/>
	</joint>
	<link name="side_bottom_face">
		<!--TODO set proper inertia-->
		<inertial>
			<origin rpy="0 0 0" xyz="0.0 0.0 0.0"/>
			<mass value="0.1"/>
			<inertia ixx="0.1" ixy="0.0" ixz="0.0" iyy="0.1" iyz="0.0" izz="0.1"/>
		</inertial>
		<visual>
			<origin rpy="0 0 0" xyz="0.0 0.0 0.0"/>
			<geometry>
				<mesh filename="full/side_bottom_face.obj"/>
			</geometry>
			<material name="gray"/>
		</visual>
	</link>
	<joint name="side_top_face_joint" type="fixed">
		<parent link="side_bottom_face"/>
		<child link="side_top_face"/>
		<origin rpy="0 0 0" xyz="0.0 0.0 0.5084191"/>
	</joint>
	<link name="side_top_face">
		<!--TODO set proper inertia-->
		<inertial>
			<origin rpy="0 0 0" xyz="0.0 0.0 0.0"/>
			<mass value="0.1"/>
			<inertia ixx="0.1" ixy="0.0" ixz="0.0" iyy="0.1" iyz="0.0" izz="0.1"/>
		</inertial>
		<visual>
			<origin rpy="0 0 0" xyz="0.0 0.0 0.0"/>
			<geometry>
				<mesh filename="full/side_top_face.obj"/>
			</geometry>
			<material name="gray"/>
		</visual>
	</link>
	<joint name="cabinet_4_joint" type="revolute">
		<axis xyz="0 0 1"/>
		<limit effort="10.0" lower="0.0" upper="3.14" velocity="0.5"/>
		<parent link="side_top_face"/>
		<child link="cabinet_4"/>
		<origin rpy="0 0 0" xyz="-0.0018 0.017 0.484"/>
		<dynamics damping="3.0" friction="3.0"/>
	</joint>
	<link name="cabinet_4">
		<!--TODO set proper inertia-->
		<inertial>
			<origin rpy="0 0 0" xyz="0.0 0.0 0.0"/>
			<mass value="0.1"/>
			<inertia ixx="0.1" ixy="0.0" ixz="0.0" iyy="0.1" iyz="0.0" izz="0.1"/>
		</inertial>
		<visual>
			<origin rpy="0 0 0" xyz="0.00305 -0.0106 0.0"/>
			<geometry>
				<mesh filename="full/cabinet_door_4.obj"/>
			</geometry>
			<material name="blue"/>
		</visual>
	</link>
	<joint name="paddle_latch_housing_joint" type="fixed">
		<parent link="cabinet_4"/>
		<child link="paddle_latch_housing"/>
		<origin rpy="0 0 0" xyz="0.2043 -0.007 0.1313"/>
	</joint>
	<link name="paddle_latch_housing">
		<!--TODO set proper inertia-->
		<inertial>
			<origin rpy="0 0 0" xyz="0.0 0.0 0.0"/>
			<mass value="0.1"/>
			<inertia ixx="0.1" ixy="0.0" ixz="0.0" iyy="0.1" iyz="0.0" izz="0.1"/>
		</inertial>
		<visual>
			<origin rpy="0 0 0" xyz="0.00305 0.0 0.00305"/>
			<geometry>
				<mesh filename="full/paddle_latch_housing.obj"/>
			</geometry>
			<material name="gray"/>
		</visual>
	</link>
	<joint name="paddle_latch_handle_joint" type="revolute">
		<axis xyz="0 0 -1"/>
		<limit effort="10.0" lower="0.0" upper="0.785375" velocity="0.5"/>
		<parent link="paddle_latch_housing"/>
		<child link="paddle_latch_handle"/>
		<origin rpy="0 0 0" xyz="0.06693 -0.003531 0.0107"/>
		<dynamics damping="3.0" friction="3.0"/>
	</joint>
	<link name="paddle_latch_handle">
		<!--TODO set proper inertia-->
		<inertial>
			<origin rpy="0 0 0" xyz="0.0 0.0 0.0"/>
			<mass value="0.1"/>
			<inertia ixx="0.1" ixy="0.0" ixz="0.0" iyy="0.1" iyz="0.0" izz="0.1"/>
		</inertial>
		<visual>
			<origin rpy="0 0 0" xyz="0.0 0.0 0.0"/>
			<geometry>
				<mesh filename="full/paddle_latch_handle.obj"/>
			</geometry>
			<material name="blue"/>
		</visual>
	</link>
	<joint name="drawer_1_joint" type="prismatic">
		<axis xyz="0 1 0"/>
		<limit effort="10.0" lower="0.0" upper="0.305" velocity="0.5"/>
		<parent link="side_top_face"/>
		<child link="drawer_1_face"/>
		<origin rpy="0 0 0" xyz="0.011 0.003 0.283"/>
		<dynamics damping="3.0" friction="3.0"/>
	</joint>
	<link name="drawer_1_face">
		<!--TODO set proper inertia-->
		<inertial>
			<origin rpy="0 0 0" xyz="0.0 0.0 0.0"/>
			<mass value="0.1"/>
			<inertia ixx="0.1" ixy="0.0" ixz="0.0" iyy="0.1" iyz="0.0" izz="0.1"/>
		</inertial>
		<visual>
			<origin rpy="0 0 0" xyz="0.0 0.0 0.0"/>
			<geometry>
				<mesh filename="full/drawer_1_face.obj"/>
			</geometry>
			<material name="blue"/>
		</visual>
	</link>
	<joint name="drawer_1_left_joint" type="fixed">
		<parent link="drawer_1_face"/>
		<child link="drawer_1_left"/>
		<origin rpy="0 0 0" xyz="0.27999999999999997 -0.305 -0.00435"/>
	</joint>
	<link name="drawer_1_left">
		<!--TODO set proper inertia-->
		<inertial>
			<origin rpy="0 0 0" xyz="0.0 0.0 0.0"/>
			<mass value="0.1"/>
			<inertia ixx="0.1" ixy="0.0" ixz="0.0" iyy="0.1" iyz="0.0" izz="0.1"/>
		</inertial>
		<visual>
			<origin rpy="0 0 0" xyz="0.0065 0.1525 0.048"/>
			<geometry>
				<box size="0.013 0.305 0.096"/>
			</geometry>
			<material name="blue"/>
		</visual>
	</link>
	<joint name="drawer_1_right_joint" type="fixed">
		<parent link="drawer_1_face"/>
		<child link="drawer_1_right"/>
		<origin rpy="0 0 0" xyz="0.0 -0.305 -0.00435"/>
	</joint>
	<link name="drawer_1_right">
		<!--TODO set proper inertia-->
		<inertial>
			<origin rpy="0 0 0" xyz="0.0 0.0 0.0"/>
			<mass value="0.1"/>
			<inertia ixx="0.1" ixy="0.0" ixz="0.0" iyy="0.1" iyz="0.0" izz="0.1"/>
		</inertial>
		<visual>
			<origin rpy="0 0 0" xyz="0.0065 0.1525 0.048"/>
			<geometry>
				<box size="0.013 0.305 0.096"/>
			</geometry>
			<material name="blue"/>
		</visual>
	</link>
	<joint name="drawer_1_bottom_joint" type="fixed">
		<parent link="drawer_1_face"/>
		<child link="drawer_1_bottom"/>
		<origin rpy="0 0 0" xyz="0.0 -0.305 -0.00435"/>
	</joint>
	<link name="drawer_1_bottom">
		<!--TODO set proper inertia-->
		<inertial>
			<origin rpy="0 0 0" xyz="0.0 0.0 0.0"/>
			<mass value="0.1"/>
			<inertia ixx="0.1" ixy="0.0" ixz="0.0" iyy="0.1" iyz="0.0" izz="0.1"/>
		</inertial>
		<visual>
			<origin rpy="0 0 0" xyz="0.1465 0.1525 0.0065"/>
			<geometry>
				<box size="0.293 0.305 0.013"/>
			</geometry>
			<material name="blue"/>
		</visual>
	</link>
	<joint name="drawer_2_joint" type="prismatic">
		<axis xyz="0 1 0"/>
		<limit effort="10.0" lower="0.0" upper="0.2921" velocity="0.5"/>
		<parent link="side_top_face"/>
		<child link="drawer_2_face"/>
		<origin rpy="0 0 0" xyz="0.011 0.003 0.086"/>
		<dynamics damping="3.0" friction="3.0"/>
	</joint>
	<link name="drawer_2_face">
		<!--TODO set proper inertia-->
		<inertial>
			<origin rpy="0 0 0" xyz="0.0 0.0 0.0"/>
			<mass value="0.1"/>
			<inertia ixx="0.1" ixy="0.0" ixz="0.0" iyy="0.1" iyz="0.0" izz="0.1"/>
		</inertial>
		<visual>
			<origin rpy="0 0 0" xyz="0.0 0.0 0.0"/>
			<geometry>
				<mesh filename="full/drawer_2_face.obj"/>
			</geometry>
			<material name="blue"/>
		</visual>
	</link>
	<joint name="recessed_latch_housing_joint" type="fixed">
		<parent link="drawer_2_face"/>
		<child link="recessed_latch_housing"/>
		<origin rpy="0 0 0" xyz="0.1148 0.003175 0.0165"/>
	</joint>
	<link name="recessed_latch_housing">
		<!--TODO set proper inertia-->
		<inertial>
			<origin rpy="0 0 0" xyz="0.0 0.0 0.0"/>
			<mass value="0.1"/>
			<inertia ixx="0.1" ixy="0.0" ixz="0.0" iyy="0.1" iyz="0.0" izz="0.1"/>
		</inertial>
		<visual>
			<origin rpy="0 0 0" xyz="0.0 0.0 0.0"/>
			<geometry>
				<mesh filename="full/recessed_latch_housing.obj"/>
			</geometry>
			<material name="gray"/>
		</visual>
	</link>
	<joint name="recessed_latch_handle_joint" type="revolute">
		<axis xyz="-1 0 0"/>
		<limit effort="10.0" lower="0.0" upper="1.5707963267948966" velocity="0.5"/>
		<parent link="recessed_latch_housing"/>
		<child link="recessed_latch_handle"/>
		<origin rpy="0 0 0" xyz="0.0508 -0.001778 0.006477"/>
		<dynamics damping="3.0" friction="3.0"/>
	</joint>
	<link name="recessed_latch_handle">
		<!--TODO set proper inertia-->
		<inertial>
			<origin rpy="0 0 0" xyz="0.0 0.0 0.0"/>
			<mass value="0.1"/>
			<inertia ixx="0.1" ixy="0.0" ixz="0.0" iyy="0.1" iyz="0.0" izz="0.1"/>
		</inertial>
		<visual>
			<origin rpy="0 0 0" xyz="0.0 0.0 0.0"/>
			<geometry>
				<mesh filename="full/recessed_latch_handle.obj"/>
			</geometry>
			<material name="blue"/>
		</visual>
	</link>
	<joint name="drawer_2_left_joint" type="fixed">
		<parent link="drawer_2_face"/>
		<child link="drawer_2_left"/>
		<origin rpy="0 0 0" xyz="0.27999999999999997 -0.305 -0.00435"/>
	</joint>
	<link name="drawer_2_left">
		<!--TODO set proper inertia-->
		<inertial>
			<origin rpy="0 0 0" xyz="0.0 0.0 0.0"/>
			<mass value="0.1"/>
			<inertia ixx="0.1" ixy="0.0" ixz="0.0" iyy="0.1" iyz="0.0" izz="0.1"/>
		</inertial>
		<visual>
			<origin rpy="0 0 0" xyz="0.0065 0.1525 0.048"/>
			<geometry>
				<box size="0.013 0.305 0.096"/>
			</geometry>
			<material name="blue"/>
		</visual>
	</link>
	<joint name="drawer_2_right_joint" type="fixed">
		<parent link="drawer_2_face"/>
		<child link="drawer_2_right"/>
		<origin rpy="0 0 0" xyz="0.0 -0.305 -0.00435"/>
	</joint>
	<link name="drawer_2_right">
		<!--TODO set proper inertia-->
		<inertial>
			<origin rpy="0 0 0" xyz="0.0 0.0 0.0"/>
			<mass value="0.1"/>
			<inertia ixx="0.1" ixy="0.0" ixz="0.0" iyy="0.1" iyz="0.0" izz="0.1"/>
		</inertial>
		<visual>
			<origin rpy="0 0 0" xyz="0.0065 0.1525 0.048"/>
			<geometry>
				<box size="0.013 0.305 0.096"/>
			</geometry>
			<material name="blue"/>
		</visual>
	</link>
	<joint name="drawer_2_bottom_joint" type="fixed">
		<parent link="drawer_2_face"/>
		<child link="drawer_2_bottom"/>
		<origin rpy="0 0 0" xyz="0.0 -0.305 -0.00435"/>
	</joint>
	<link name="drawer_2_bottom">
		<!--TODO set proper inertia-->
		<inertial>
			<origin rpy="0 0 0" xyz="0.0 0.0 0.0"/>
			<mass value="0.1"/>
			<inertia ixx="0.1" ixy="0.0" ixz="0.0" iyy="0.1" iyz="0.0" izz="0.1"/>
		</inertial>
		<visual>
			<origin rpy="0 0 0" xyz="0.1465 0.1525 0.0065"/>
			<geometry>
				<box size="0.293 0.305 0.013"/>
			</geometry>
			<material name="blue"/>
		</visual>
	</link>
	<!-- long bench
    <xacro:include filename="$(find clr_imetro_environments)/urdf/long_bench.xacro"/>
    <xacro:long_bench_seat prefix="long_bench/" parent="world">
      <origin xyz="${-0.9 - 1.2192 + 0.02 + 2.1} 1.175 0.475" rpy="0 0 4.7112"/>
    </xacro:long_bench_seat> -->
	<!--This is for when there is a bench at the level of the bottom of the hatch opening.-->
	<joint name="hatch_level_bench_joint" type="fixed">
		<parent link="bench_back"/>
		<child link="hatch_level_bench"/>
		<origin rpy="0 0 0" xyz="0.706 0.895 0.0"/>
	</joint>
	<link name="hatch_level_bench">
		<visual>
			<origin rpy="0 0 0" xyz="-0.6096 0.5965 0.02635"/>
			<geometry>
				<box size="1.2192 1.193 0.0527"/>
			</geometry>
			<material name="gray"/>
		</visual>
	</link>
	<!-- Plane -->
	<link name="ground_plane">
		<visual>
			<origin rpy="0 0 0" xyz="0 0 0"/>
			<geometry>
				<box size="20 20 0.01"/>
			</geometry>
			<material name="Grey">
				<color rgba="1.0 1.0 1.0 0.075"/>
			</material>
		</visual>
		<inertial>
			<mass value="0"/>
			<inertia ixx="0" ixy="0" ixz="0" iyy="0" iyz="0" izz="0"/>
		</inertial>
	</link>
	<joint name="ground_joint" type="fixed">
		<parent link="world"/>
		<child link="ground_plane"/>
		<origin rpy="0 0 0" xyz="0 0 -0.005"/>
	</joint>
	<!-- Plane -->
	<link name="room_ceiling">
		<visual>
			<origin rpy="0 0 0" xyz="0 0 0"/>
			<geometry>
				<box size="20 20 0.01"/>
			</geometry>
			<material name="Grey">
				<color rgba="1.0 1.0 1.0 0.075"/>
			</material>
		</visual>
		<inertial>
			<mass value="0"/>
			<inertia ixx="0" ixy="0" ixz="0" iyy="0" iyz="0" izz="0"/>
		</inertial>
	</link>
	<joint name="room_ceiling_joint" type="fixed">
		<parent link="world"/>
		<child link="room_ceiling"/>
		<origin rpy="0 0 0" xyz="0 0 2.75"/>
	</joint>
	<ros2_control name="MujocoSystem" type="system">
		<hardware>
			<plugin>mujoco_ros2_simulation/MujocoSystemInterface</plugin>
			<param name="mujoco_model">/home/er4-user/ws/install/clr_mujoco_config/share/clr_mujoco_config/description/scene.xml</param>
		</hardware>
		<joint name="vention_rail_base_to_carriage">
			<command_interface name="position"/>
			<state_interface name="position">
				<param name="initial_value">0.0</param>
			</state_interface>
			<state_interface name="velocity"/>
			<state_interface name="effort"/>
		</joint>
		<joint name="ewellix_lift_lower_to_higher">
			<command_interface name="position"/>
			<state_interface name="position">
				<param name="initial_value">0.0</param>
			</state_interface>
			<state_interface name="velocity"/>
			<state_interface name="effort"/>
		</joint>
		<joint name="shoulder_pan_joint">
			<command_interface name="position"/>
			<state_interface name="position">
				<param name="initial_value">2.5656340004316642</param>
			</state_interface>
			<state_interface name="velocity"/>
			<state_interface name="effort"/>
		</joint>
		<joint name="shoulder_lift_joint">
			<command_interface name="position"/>
			<state_interface name="position">
				<param name="initial_value">-3.001966313430247</param>
			</state_interface>
			<state_interface name="velocity"/>
			<state_interface name="effort"/>
		</joint>
		<joint name="elbow_joint">
			<command_interface name="position"/>
			<state_interface name="position">
				<param name="initial_value">-0.9599310885968813</param>
			</state_interface>
			<state_interface name="velocity"/>
			<state_interface name="effort"/>
		</joint>
		<joint name="wrist_1_joint">
			<command_interface name="position"/>
			<state_interface name="position">
				<param name="initial_value">-0.6981317007977318</param>
			</state_interface>
			<state_interface name="velocity"/>
			<state_interface name="effort"/>
		</joint>
		<joint name="wrist_2_joint">
			<command_interface name="position"/>
			<state_interface name="position">
				<param name="initial_value">-1.5184364492350666</param>
			</state_interface>
			<state_interface name="velocity"/>
			<state_interface name="effort"/>
		</joint>
		<joint name="wrist_3_joint">
			<command_interface name="position"/>
			<state_interface name="position">
				<param name="initial_value">2.111848394913139</param>
			</state_interface>
			<state_interface name="velocity"/>
			<state_interface name="effort"/>
		</joint>
		<!-- Robotiq gripper -->
		<joint name="finger_1_joint">
			<command_interface name="position"/>
			<state_interface name="position">
				<param name="initial_value">0.025</param>
			</state_interface>
			<state_interface name="velocity"/>
			<state_interface name="effort"/>
		</joint>
		<sensor name="tcp_fts_sensor">
			<param name="mujoco_type">fts</param>
			<param name="mujoco_sensor_name">tcp_fts_sensor</param>
			<state_interface name="force.x"/>
			<state_interface name="force.y"/>
			<state_interface name="force.z"/>
			<state_interface name="torque.x"/>
			<state_interface name="torque.y"/>
			<state_interface name="torque.z"/>
		</sensor>
		<!-- Mockups -->
		<joint name="door_to_frame_joint">
			<state_interface name="position"/>
		</joint>
		<joint name="housing_to_latch_lock">
			<state_interface name="position"/>
		</joint>
		<joint name="housing_to_left_latch_pull">
			<state_interface name="position"/>
		</joint>
		<joint name="housing_to_right_latch_pull">
			<state_interface name="position"/>
		</joint>
		<joint name="lorge/hatch_outer_frame_face_joint">
			<state_interface name="position"/>
		</joint>
		<joint name="lorge/external_rotary_joint">
			<state_interface name="position"/>
		</joint>
		<joint name="lorge/external_rotary_handle_joint">
			<state_interface name="position"/>
		</joint>
		<joint name="lorge/internal_rotary_joint">
			<state_interface name="position"/>
		</joint>
		<joint name="lorge/internal_rotary_handle_joint">
			<state_interface name="position"/>
		</joint>
		<joint name="bench_lid_joint">
			<state_interface name="position"/>
		</joint>
		<joint name="cabinet_1_joint">
			<state_interface name="position"/>
		</joint>
		<joint name="cabinet_2_joint">
			<state_interface name="position"/>
		</joint>
		<joint name="round_latch_joint">
			<state_interface name="position"/>
		</joint>
		<joint name="push_latch_button_joint">
			<state_interface name="position"/>
		</joint>
		<joint name="push_latch_handle_joint">
			<state_interface name="position"/>
		</joint>
		<joint name="cabinet_3_joint">
			<state_interface name="position"/>
		</joint>
		<joint name="cabinet_4_joint">
			<state_interface name="position"/>
		</joint>
		<joint name="paddle_latch_handle_joint">
			<state_interface name="position"/>
		</joint>
		<joint name="drawer_1_joint">
			<state_interface name="position"/>
		</joint>
		<joint name="drawer_2_joint">
			<state_interface name="position"/>
		</joint>
		<joint name="recessed_latch_handle_joint">
			<state_interface name="position"/>
		</joint>
	</ros2_control>
	<mujoco>
		<compiler meshdir="assets" balanceinertia="true" discardvisual="false" strippath="false"/>
	</mujoco>
</robot>
